<model name="Pioneer3AT">
  <pose>-4.80000 4.20000 0.1720000 0.000000 0.000000 90.00000</pose>
  <static>0</static>
  <link name="chassis">
    <inertial>
      <mass>14.000000</mass>
      <inertia>
        <ixx>0.333800</ixx>
        <ixy>0.000000</ixy>
        <ixz>0.000000</ixz>
        <iyy>0.478300</iyy>
        <iyz>0.000000</iyz>
        <izz>0.333800</izz>
      </inertia>
    </inertial>
    <collision name="collision">
      <geometry>
        <box>
          <size>0.501000 0.400000 0.190000</size>
        </box>
      </geometry>
      <surface>
        <bounce />
        <friction>
          <ode />
        </friction>
        <contact>
          <ode />
        </contact>
      </surface>
    </collision>
    <visual name="visual">
      <geometry>
        <mesh>
          <uri>model://pioneer3at/meshes/chassis.dae</uri>
        </mesh>
      </geometry>
    </visual>
    <velocity_decay>
      <linear>0.000000</linear>
      <angular>0.000000</angular>
    </velocity_decay>
    <self_collide>0</self_collide>
    <kinematic>0</kinematic>
    <gravity>1</gravity>
  </link>
  <link name="right_front_wheel">
    <pose>0.125000 -0.201000 -0.060000 1.570700 0.000000 0.000000</pose>
    <collision name="collision">
      <geometry>
        <cylinder>
          <radius>0.110000</radius>
          <length>0.075000</length>
        </cylinder>
      </geometry>
      <surface>
        <friction>
          <ode>
            <mu>1.000000</mu>
            <mu2>1.000000</mu2>
            <slip1>0.500000</slip1>
            <slip2>0.000000</slip2>
          </ode>
        </friction>
        <bounce />
        <contact>
          <ode />
        </contact>
      </surface>
    </collision>
    <visual name="visual">
      <geometry>
        <mesh>
          <uri>model://pioneer3at/meshes/wheel.dae</uri>
        </mesh>
      </geometry>
    </visual>
    <velocity_decay>
      <linear>0.000000</linear>
      <angular>0.000000</angular>
    </velocity_decay>
    <self_collide>0</self_collide>
    <inertial>
      <inertia>
        <ixx>1.000000</ixx>
        <ixy>0.000000</ixy>
        <ixz>0.000000</ixz>
        <iyy>1.000000</iyy>
        <iyz>0.000000</iyz>
        <izz>1.000000</izz>
      </inertia>
      <mass>1.000000</mass>
    </inertial>
    <kinematic>0</kinematic>
    <gravity>1</gravity>
  </link>
  <link name="left_front_wheel">
    <pose>0.125000 0.201000 -0.060000 1.570700 0.000000 0.000000</pose>
    <collision name="collision">
      <geometry>
        <cylinder>
          <radius>0.110000</radius>
          <length>0.075000</length>
        </cylinder>
      </geometry>
      <surface>
        <friction>
          <ode>
            <mu>1.000000</mu>
            <mu2>1.000000</mu2>
            <slip1>0.500000</slip1>
            <slip2>0.000000</slip2>
          </ode>
        </friction>
        <bounce />
        <contact>
          <ode />
        </contact>
      </surface>
    </collision>
    <visual name="visual">
      <geometry>
        <mesh>
          <uri>model://pioneer3at/meshes/wheel.dae</uri>
        </mesh>
      </geometry>
    </visual>
    <velocity_decay>
      <linear>0.000000</linear>
      <angular>0.000000</angular>
    </velocity_decay>
    <self_collide>0</self_collide>
    <inertial>
      <inertia>
        <ixx>1.000000</ixx>
        <ixy>0.000000</ixy>
        <ixz>0.000000</ixz>
        <iyy>1.000000</iyy>
        <iyz>0.000000</iyz>
        <izz>1.000000</izz>
      </inertia>
      <mass>1.000000</mass>
    </inertial>
    <kinematic>0</kinematic>
    <gravity>1</gravity>
  </link>
  <link name="right_rear_wheel">
    <pose>-0.125000 -0.201000 -0.060000 1.570700 0.000000 0.000000</pose>
    <collision name="collision">
      <geometry>
        <cylinder>
          <radius>0.110000</radius>
          <length>0.075000</length>
        </cylinder>
      </geometry>
      <surface>
        <friction>
          <ode>
            <mu>1.000000</mu>
            <mu2>1.000000</mu2>
            <slip1>0.500000</slip1>
            <slip2>0.000000</slip2>
          </ode>
        </friction>
        <bounce />
        <contact>
          <ode />
        </contact>
      </surface>
    </collision>
    <visual name="visual">
      <geometry>
        <mesh>
          <uri>model://pioneer3at/meshes/wheel.dae</uri>
        </mesh>
      </geometry>
    </visual>
    <velocity_decay>
      <linear>0.000000</linear>
      <angular>0.000000</angular>
    </velocity_decay>
    <self_collide>0</self_collide>
    <inertial>
      <inertia>
        <ixx>1.000000</ixx>
        <ixy>0.000000</ixy>
        <ixz>0.000000</ixz>
        <iyy>1.000000</iyy>
        <iyz>0.000000</iyz>
        <izz>1.000000</izz>
      </inertia>
      <mass>1.000000</mass>
    </inertial>
    <kinematic>0</kinematic>
    <gravity>1</gravity>
  </link>
  <link name="left_rear_wheel">
    <pose>-0.125000 0.201000 -0.060000 1.570700 0.000000 0.000000</pose>
    <collision name="collision">
      <geometry>
        <cylinder>
          <radius>0.110000</radius>
          <length>0.075000</length>
        </cylinder>
      </geometry>
      <surface>
        <friction>
          <ode>
            <mu>1.000000</mu>
            <mu2>1.000000</mu2>
            <slip1>0.500000</slip1>
            <slip2>0.000000</slip2>
          </ode>
        </friction>
        <bounce />
        <contact>
          <ode />
        </contact>
      </surface>
    </collision>
    <visual name="visual">
      <geometry>
        <mesh>
          <uri>model://pioneer3at/meshes/wheel.dae</uri>
        </mesh>
      </geometry>
    </visual>
    <velocity_decay>
      <linear>0.000000</linear>
      <angular>0.000000</angular>
    </velocity_decay>
    <self_collide>0</self_collide>
    <inertial>
      <inertia>
        <ixx>1.000000</ixx>
        <ixy>0.000000</ixy>
        <ixz>0.000000</ixz>
        <iyy>1.000000</iyy>
        <iyz>0.000000</iyz>
        <izz>1.000000</izz>
      </inertia>
      <mass>1.000000</mass>
    </inertial>
    <kinematic>0</kinematic>
    <gravity>1</gravity>
  </link>
  <joint name="right_front" type="revolute">
    <pose>0.000000 0.000000 0.000000 0.000000 0.000000 0.000000</pose>
    <child>right_front_wheel</child>
    <parent>chassis</parent>
    <axis>
      <xyz>0.000000 1.000000 0.000000</xyz>
      <limit>
        <lower>-10000000000000000.000000</lower>
        <upper>10000000000000000.000000</upper>
      </limit>
    </axis>
  </joint>
  <joint name="right_rear" type="revolute">
    <pose>0.000000 0.000000 0.000000 0.000000 0.000000 0.000000</pose>
    <child>right_rear_wheel</child>
    <parent>chassis</parent>
    <axis>
      <xyz>0.000000 1.000000 0.000000</xyz>
      <limit>
        <lower>-10000000000000000.000000</lower>
        <upper>10000000000000000.000000</upper>
      </limit>
    </axis>
  </joint>
  <joint name="left_front" type="revolute">
    <pose>0.000000 0.000000 0.000000 0.000000 0.000000 0.000000</pose>
    <child>left_front_wheel</child>
    <parent>chassis</parent>
    <axis>ir
      <xyz>0.000000 1.000000 0.000000</xyz>
      <limit>
        <lower>-10000000000000000.000000</lower>
        <upper>10000000000000000.000000</upper>
      </limit>
    </axis>
  </joint>
  <joint name="left_rear" type="revolute">
    <pose>0.000000 0.000000 0.000000 0.000000 0.000000 0.000000</pose>
    <child>left_rear_wheel</child>
    <parent>chassis</parent>
    <axis>
      <xyz>0.000000 1.000000 0.000000</xyz>
      <limit>
        <lower>-10000000000000000.000000</lower>
        <upper>10000000000000000.000000</upper>
      </limit>
    </axis>
  </joint>
  <link name="hokuyo::link">
    <inertial>
      <mass>0.100000</mass>
      <inertia>
        <ixx>1.000000</ixx>
        <ixy>0.000000</ixy>
        <ixz>0.000000</ixz>
        <iyy>1.000000</iyy>
        <iyz>0.000000</iyz>
        <izz>1.000000</izz>
      </inertia>
    </inertial>
    <visual name="visual">
      <geometry>
        <mesh>
          <uri>model://hokuyo/meshes/hokuyo.dae</uri>
        </mesh>
      </geometry>
    </visual>
    <collision name="collision-base">
      <pose>0.000000 0.000000 -0.014500 0.000000 0.000000 0.000000</pose>
      <geometry>
        <box>
          <size>0.050000 0.050000 0.041000</size>
        </box>
      </geometry>
      <surface>
        <bounce />
        <friction>
          <ode />
        </friction>
        <contact>
          <ode />
        </contact>
      </surface>
    </collision>
    <collision name="collision-top">
      <pose>0.000000 0.000000 0.020500 0.000000 0.000000 0.000000</pose>
      <geometry>
        <cylinder>
          <radius>0.021000</radius>
          <length>0.029000</length>
        </cylinder>
      </geometry>
      <surface>
        <bounce />
        <friction>
          <ode />
        </friction>
        <contact>
          <ode />
        </contact>
      </surface>
    </collision>
    <sensor name="laser" type="ray">
      <pose>0.010000 0.000000 0.017500 0.000000 0.000000 0.000000</pose>
      <ray>
        <scan>
          <horizontal>
            <samples>640</samples>
            <resolution>1.000000</resolution>
            <!--<min_angle>-2.268890</min_angle>
            <max_angle>2.268899</max_angle>-->
            <min_angle>-1.57079632679</min_angle>
            <max_angle>1.57079632679</max_angle>
          </horizontal>
        </scan>
        <range>
          <min>0.080000</min>
          <max>10.000000</max>
          <resolution>0.010000</resolution>
        </range>
      </ray>
      <plugin name="laser" filename="libRayPlugin.so" />
      <always_on>1</always_on>
      <update_rate>30.000000</update_rate>
      <visualize>1</visualize>
    </sensor>
    <velocity_decay>
      <linear>0.000000</linear>
      <angular>0.000000</angular>
    </velocity_decay>
    <pose>0.200000 0.000000 0.130000 0.000000 0.000000 0.000000</pose>
    <self_collide>0</self_collide>
    <kinematic>0</kinematic>
    <gravity>1</gravity>
  </link>
  <joint name="hokuyo_joint" type="revolute">
    <child>hokuyo::link</child>
    <parent>chassis</parent>
    <axis>
      <xyz>0.000000 0.000000 1.000000</xyz>
      <limit>
        <upper>0.000000</upper>
        <lower>0.000000</lower>
      </limit>
    </axis>
  </joint>
  <plugin name="SkidSteerDrivePlugin" filename="libSkidSteerDrivePlugin.so" />
</model>