<sdf version='1.4'>
  <world name='default'>
    <light name='sun' type='directional'>
      <cast_shadows>1</cast_shadows>
      <pose>0 0 10 0 -0 0</pose>
      <diffuse>0.8 0.8 0.8 1</diffuse>
      <specular>0.2 0.2 0.2 1</specular>
      <attenuation>
        <range>1000</range>
        <constant>0.9</constant>
        <linear>0.01</linear>
        <quadratic>0.001</quadratic>
      </attenuation>
      <direction>-0.5 0.1 -0.9</direction>
    </light>
    <model name='ground_plane'>
      <static>1</static>
      <link name='link'>
        <collision name='collision'>
          <geometry>
            <plane>
              <normal>0 0 1</normal>
              <size>100 100</size>
            </plane>
          </geometry>
          <surface>
            <friction>
              <ode>
                <mu>100</mu>
                <mu2>50</mu2>
              </ode>
            </friction>
            <bounce/>
            <contact>
              <ode/>
            </contact>
          </surface>
          <max_contacts>10</max_contacts>
        </collision>
        <visual name='visual'>
          <cast_shadows>0</cast_shadows>
          <geometry>
            <plane>
              <normal>0 0 1</normal>
              <size>100 100</size>
            </plane>
          </geometry>
          <material>
            <script>
              <uri>file://media/materials/scripts/gazebo.material</uri>
              <name>Gazebo/Grey</name>
            </script>
          </material>
        </visual>
        <velocity_decay>
          <linear>0</linear>
          <angular>0</angular>
        </velocity_decay>
        <self_collide>0</self_collide>
        <kinematic>0</kinematic>
        <gravity>1</gravity>
      </link>
    </model>
    <physics type='ode'>
      <max_step_size>0.001</max_step_size>
      <real_time_factor>1</real_time_factor>
      <real_time_update_rate>1000</real_time_update_rate>
      <gravity>0 0 -9.8</gravity>
    </physics>
    <scene>
      <ambient>0.4 0.4 0.4 1</ambient>
      <background>0.7 0.7 0.7 1</background>
      <shadows>1</shadows>
    </scene>
    <spherical_coordinates>
      <surface_model>EARTH_WGS84</surface_model>
      <latitude_deg>0</latitude_deg>
      <longitude_deg>0</longitude_deg>
      <elevation>0</elevation>
      <heading_deg>0</heading_deg>
    </spherical_coordinates>
    <model name='Pioneer3AT'>
      <pose>0.5 9.5 0.172 0 0 -1.57</pose>
      <static>0</static>
      <link name='chassis'>
        <inertial>
          <mass>14</mass>
          <inertia>
            <ixx>0.3338</ixx>
            <ixy>0</ixy>
            <ixz>0</ixz>
            <iyy>0.4783</iyy>
            <iyz>0</iyz>
            <izz>0.3338</izz>
          </inertia>
        </inertial>
        <collision name='collision'>
          <geometry>
            <box>
              <size>0.501 0.4 0.19</size>
            </box>
          </geometry>
          <surface>
            <bounce/>
            <friction>
              <ode/>
            </friction>
            <contact>
              <ode/>
            </contact>
          </surface>
          <max_contacts>10</max_contacts>
        </collision>
        <visual name='visual'>
          <geometry>
            <mesh>
              <uri>model://pioneer3at/meshes/chassis.dae</uri>
            </mesh>
          </geometry>
        </visual>
        <velocity_decay>
          <linear>0</linear>
          <angular>0</angular>
        </velocity_decay>
        <self_collide>0</self_collide>
        <kinematic>0</kinematic>
        <gravity>1</gravity>
      </link>
      <link name='right_front_wheel'>
        <pose>0.125 -0.201 -0.06 1.5707 -0 0</pose>
        <collision name='collision'>
          <geometry>
            <cylinder>
              <radius>0.11</radius>
              <length>0.075</length>
            </cylinder>
          </geometry>
          <surface>
            <friction>
              <ode>
                <mu>1</mu>
                <mu2>1</mu2>
                <slip1>0.5</slip1>
                <slip2>0</slip2>
              </ode>
            </friction>
            <bounce/>
            <contact>
              <ode/>
            </contact>
          </surface>
          <max_contacts>10</max_contacts>
        </collision>
        <visual name='visual'>
          <geometry>
            <mesh>
              <uri>model://pioneer3at/meshes/wheel.dae</uri>
            </mesh>
          </geometry>
        </visual>
        <velocity_decay>
          <linear>0</linear>
          <angular>0</angular>
        </velocity_decay>
        <self_collide>0</self_collide>
        <inertial>
          <inertia>
            <ixx>1</ixx>
            <ixy>0</ixy>
            <ixz>0</ixz>
            <iyy>1</iyy>
            <iyz>0</iyz>
            <izz>1</izz>
          </inertia>
          <mass>1</mass>
        </inertial>
        <kinematic>0</kinematic>
        <gravity>1</gravity>
      </link>
      <link name='left_front_wheel'>
        <pose>0.125 0.201 -0.06 1.5707 -0 0</pose>
        <collision name='collision'>
          <geometry>
            <cylinder>
              <radius>0.11</radius>
              <length>0.075</length>
            </cylinder>
          </geometry>
          <surface>
            <friction>
              <ode>
                <mu>1</mu>
                <mu2>1</mu2>
                <slip1>0.5</slip1>
                <slip2>0</slip2>
              </ode>
            </friction>
            <bounce/>
            <contact>
              <ode/>
            </contact>
          </surface>
          <max_contacts>10</max_contacts>
        </collision>
        <visual name='visual'>
          <geometry>
            <mesh>
              <uri>model://pioneer3at/meshes/wheel.dae</uri>
            </mesh>
          </geometry>
        </visual>
        <velocity_decay>
          <linear>0</linear>
          <angular>0</angular>
        </velocity_decay>
        <self_collide>0</self_collide>
        <inertial>
          <inertia>
            <ixx>1</ixx>
            <ixy>0</ixy>
            <ixz>0</ixz>
            <iyy>1</iyy>
            <iyz>0</iyz>
            <izz>1</izz>
          </inertia>
          <mass>1</mass>
        </inertial>
        <kinematic>0</kinematic>
        <gravity>1</gravity>
      </link>
      <link name='right_rear_wheel'>
        <pose>-0.125 -0.201 -0.06 1.5707 -0 0</pose>
        <collision name='collision'>
          <geometry>
            <cylinder>
              <radius>0.11</radius>
              <length>0.075</length>
            </cylinder>
          </geometry>
          <surface>
            <friction>
              <ode>
                <mu>1</mu>
                <mu2>1</mu2>
                <slip1>0.5</slip1>
                <slip2>0</slip2>
              </ode>
            </friction>
            <bounce/>
            <contact>
              <ode/>
            </contact>
          </surface>
          <max_contacts>10</max_contacts>
        </collision>
        <visual name='visual'>
          <geometry>
            <mesh>
              <uri>model://pioneer3at/meshes/wheel.dae</uri>
            </mesh>
          </geometry>
        </visual>
        <velocity_decay>
          <linear>0</linear>
          <angular>0</angular>
        </velocity_decay>
        <self_collide>0</self_collide>
        <inertial>
          <inertia>
            <ixx>1</ixx>
            <ixy>0</ixy>
            <ixz>0</ixz>
            <iyy>1</iyy>
            <iyz>0</iyz>
            <izz>1</izz>
          </inertia>
          <mass>1</mass>
        </inertial>
        <kinematic>0</kinematic>
        <gravity>1</gravity>
      </link>
      <link name='left_rear_wheel'>
        <pose>-0.125 0.201 -0.06 1.5707 -0 0</pose>
        <collision name='collision'>
          <geometry>
            <cylinder>
              <radius>0.11</radius>
              <length>0.075</length>
            </cylinder>
          </geometry>
          <surface>
            <friction>
              <ode>
                <mu>1</mu>
                <mu2>1</mu2>
                <slip1>0.5</slip1>
                <slip2>0</slip2>
              </ode>
            </friction>
            <bounce/>
            <contact>
              <ode/>
            </contact>
          </surface>
          <max_contacts>10</max_contacts>
        </collision>
        <visual name='visual'>
          <geometry>
            <mesh>
              <uri>model://pioneer3at/meshes/wheel.dae</uri>
            </mesh>
          </geometry>
        </visual>
        <velocity_decay>
          <linear>0</linear>
          <angular>0</angular>
        </velocity_decay>
        <self_collide>0</self_collide>
        <inertial>
          <inertia>
            <ixx>1</ixx>
            <ixy>0</ixy>
            <ixz>0</ixz>
            <iyy>1</iyy>
            <iyz>0</iyz>
            <izz>1</izz>
          </inertia>
          <mass>1</mass>
        </inertial>
        <kinematic>0</kinematic>
        <gravity>1</gravity>
      </link>
      <joint name='right_front' type='revolute'>
        <pose>0 0 0 0 -0 0</pose>
        <child>right_front_wheel</child>
        <parent>chassis</parent>
        <axis>
          <xyz>0 1 0</xyz>
          <limit>
            <lower>-1e+16</lower>
            <upper>1e+16</upper>
          </limit>
        </axis>
      </joint>
      <joint name='right_rear' type='revolute'>
        <pose>0 0 0 0 -0 0</pose>
        <child>right_rear_wheel</child>
        <parent>chassis</parent>
        <axis>
          <xyz>0 1 0</xyz>
          <limit>
            <lower>-1e+16</lower>
            <upper>1e+16</upper>
          </limit>
        </axis>
      </joint>
      <joint name='left_front' type='revolute'>
        <pose>0 0 0 0 -0 0</pose>
        <child>left_front_wheel</child>
        <parent>chassis</parent>
        <axis>
          <xyz>0 1 0</xyz>
          <limit>
            <lower>-1e+16</lower>
            <upper>1e+16</upper>
          </limit>
        </axis>
      </joint>
      <joint name='left_rear' type='revolute'>
        <pose>0 0 0 0 -0 0</pose>
        <child>left_rear_wheel</child>
        <parent>chassis</parent>
        <axis>
          <xyz>0 1 0</xyz>
          <limit>
            <lower>-1e+16</lower>
            <upper>1e+16</upper>
          </limit>
        </axis>
      </joint>
      <link name='hokuyo::link'>
        <inertial>
          <mass>0.1</mass>
          <inertia>
            <ixx>1</ixx>
            <ixy>0</ixy>
            <ixz>0</ixz>
            <iyy>1</iyy>
            <iyz>0</iyz>
            <izz>1</izz>
          </inertia>
        </inertial>
        <visual name='visual'>
          <geometry>
            <mesh>
              <uri>model://hokuyo/meshes/hokuyo.dae</uri>
            </mesh>
          </geometry>
        </visual>
        <collision name='collision-base'>
          <pose>0 0 -0.0145 0 -0 0</pose>
          <geometry>
            <box>
              <size>0.05 0.05 0.041</size>
            </box>
          </geometry>
          <surface>
            <bounce/>
            <friction>
              <ode/>
            </friction>
            <contact>
              <ode/>
            </contact>
          </surface>
          <max_contacts>10</max_contacts>
        </collision>
        <collision name='collision-top'>
          <pose>0 0 0.0205 0 -0 0</pose>
          <geometry>
            <cylinder>
              <radius>0.021</radius>
              <length>0.029</length>
            </cylinder>
          </geometry>
          <surface>
            <bounce/>
            <friction>
              <ode/>
            </friction>
            <contact>
              <ode/>
            </contact>
          </surface>
          <max_contacts>10</max_contacts>
        </collision>
        <sensor name='laser' type='ray'>
          <pose>0.01 0 0.0175 0 -0 0</pose>
          <ray>
            <scan>
              <horizontal>
                <samples>640</samples>
                <resolution>1</resolution>
                <min_angle>-1.5708</min_angle>
                <max_angle>1.5708</max_angle>
              </horizontal>
            </scan>
            <range>
              <min>0.08</min>
              <max>10</max>
              <resolution>0.01</resolution>
            </range>
          </ray>
          <plugin name='laser' filename='libRayPlugin.so'/>
          <always_on>1</always_on>
          <update_rate>30</update_rate>
          <visualize>0</visualize>
        </sensor>
        <velocity_decay>
          <linear>0</linear>
          <angular>0</angular>
        </velocity_decay>
        <pose>0.2 0 0.13 0 -0 0</pose>
        <self_collide>0</self_collide>
        <kinematic>0</kinematic>`
        <gravity>1</gravity>
      </link>
      <joint name='hokuyo_joint' type='revolute'>
        <child>hokuyo::link</child>
        <parent>chassis</parent>
        <axis>
          <xyz>0 0 1</xyz>
          <limit>
            <upper>0</upper>
            <lower>0</lower>
          </limit>
        </axis>
      </joint>
      <plugin name='SkidSteerDrivePlugin' filename='libSkidSteerDrivePlugin.so'>
        <MaxForce>5.0</MaxForce>
      </plugin>
      
      <!-- COUNTER WEIGHT -->
      <link name='counter_weight'>
        <pose>-0.27 0.0 0.0 0 1.57 0</pose>
        <inertial>
          <mass>1.3</mass>
          <inertia>
            <ixx>2</ixx>
            <ixy>0</ixy>
            <ixz>0</ixz>
            <iyy>2</iyy>
            <iyz>0</iyz>
            <izz>2</izz>
          </inertia>
        </inertial>
        <collision name='collision'>
          <geometry>
            <box>
              <size>0.15 0.15 0.3</size>
            </box>
          </geometry>
          <max_contacts>10</max_contacts>
          <surface>
            <contact>
              <ode/>
            </contact>
            <bounce/>
            <friction>
              <ode/>
            </friction>
          </surface>
        </collision>
        <visual name='visual'>
          <geometry>
            <box>
              <size>0.15 0.15 0.03</size>
            </box>
          </geometry>
          <material>
            <script>
              <uri>file://media/materials/scripts/gazebo.material</uri>
              <name>Gazebo/Grey</name>
            </script>
          </material>
        </visual>
        <self_collide>0</self_collide>
        <kinematic>0</kinematic>
        <gravity>1</gravity>
      </link>

      <joint name="weight_base_joint" type="revolute">
        <parent>chassis</parent>
        <child>counter_weight</child>
        <axis>
          <limit>
            <lower>0</lower>
            <upper>0</upper>
          </limit>
          <xyz>0 0 1</xyz>
        </axis>
      </joint>

      <!-- GRIPPER gripper -->

     <link name='base_link'>
        <pose>0.31 0 0 0 0 -1.57</pose>
        <inertial>
          <pose>0 0 0 0 -0 0</pose>
          <mass>1.3</mass>
          <inertia>
            <ixx>0.0035</ixx>
            <ixy>0</ixy>
            <ixz>0</ixz>
            <iyy>0.0035</iyy>
            <iyz>0</iyz>
            <izz>0.0035</izz>
          </inertia>
        </inertial>
        <collision name='base_link_collision'>
          <pose>0 0 0 0 -0 0</pose>
          <geometry>
            <box>
              <size>0.1 0.1 0.1</size>
            </box>
          </geometry>
          <max_contacts>10</max_contacts>
          <surface>
            <contact>
              <ode/>
            </contact>
            <bounce/>
            <friction>
              <ode/>
            </friction>
          </surface>
        </collision>
        <visual name='base_link_visual'>
          <pose>0 0 0 0 -0 0</pose>
          <geometry>
            <mesh>
              <scale>1 1 1</scale>
              <uri>model://robotiq/meshes/s-model_articulated/visual/palm.STL</uri>
            </mesh>
          </geometry>
        </visual>
        <gravity>1</gravity>
        <velocity_decay/>
        <self_collide>0</self_collide>
        <kinematic>0</kinematic>
      </link>
      <link name='l_finger_1_link_0'>
        <pose>0.331364 0.045517 0.036 3.14159 -7.34641e-06 0.00159</pose>
        <inertial>
          <pose>-0.01 0 0 0 -0 0</pose>
          <mass>0.1</mass>
          <inertia>
            <ixx>1.8e-05</ixx>
            <ixy>0</ixy>
            <ixz>0</ixz>
            <iyy>2.5e-05</iyy>
            <iyz>0</iyz>
            <izz>2.5e-05</izz>
          </inertia>
        </inertial>
        <collision name='l_finger_1_link_0_collision'>
          <pose>0 0 0 0 -0 0</pose>
          <geometry>
            <mesh>
              <scale>1 1 1</scale>
              <uri>model://robotiq/meshes/s-model_articulated/collision/link_0.STL</uri>
            </mesh>
          </geometry>
          <surface>
            <contact>
              <ode/>
            </contact>
            <friction>
              <ode>
                <mu>1.1</mu>
                <mu2>1.1</mu2>
              </ode>
            </friction>
            <bounce/>
          </surface>
          <max_contacts>10</max_contacts>
        </collision>
        <visual name='l_finger_1_link_0_visual'>
          <pose>0 0 0 0 -0 0</pose>
          <geometry>
            <mesh>
              <scale>1 1 1</scale>
              <uri>model://robotiq/meshes/s-model_articulated/visual/link_0.STL</uri>
            </mesh>
          </geometry>
        </visual>
        <gravity>1</gravity>
        <velocity_decay/>
        <self_collide>0</self_collide>
        <kinematic>0</kinematic>
      </link>
      <joint name='l_palm_finger_1_joint' type='revolute'>
        <child>l_finger_1_link_0</child>
        <parent>base_link</parent>
        <axis>
          <xyz>0.001593 -0.999999 0</xyz>
          <limit>
            <lower>-0.2967</lower>
            <upper>0.2967</upper>
            <effort>60</effort>
            <velocity>-1</velocity>
          </limit>
          <dynamics>
            <damping>1</damping>
            <friction>0</friction>
            <spring_reference>0</spring_reference>
            <spring_stiffness>0</spring_stiffness>
          </dynamics>
          <use_parent_model_frame>1</use_parent_model_frame>
        </axis>
        <physics>
          <ode>
            <implicit_spring_damper>1</implicit_spring_damper>
            <cfm_damping>1</cfm_damping>
            <limit>
              <cfm>0</cfm>
              <erp>0.2</erp>
            </limit>
          </ode>
        </physics>
      </joint>
      <link name='l_finger_1_link_1'>
        <pose>0.331364 0.045517 0.036 3.14159 3.64903e-06 2.0922</pose>
        <inertial>
          <pose>0.00053 0.03218 0 0 -0 1.5708</pose>
          <mass>0.047</mass>
          <inertia>
            <ixx>4.99332e-06</ixx>
            <ixy>9.1312e-07</ixy>
            <ixz>-1.2e-09</ixz>
            <iyy>6.43453e-05</iyy>
            <iyz>-7e-11</iyz>
            <izz>6.06192e-05</izz>
          </inertia>
        </inertial>
        <collision name='l_finger_1_link_1_collision'>
          <pose>0 0.05717 0 0 -0 1.5708</pose>
          <geometry>
            <mesh>
              <scale>1 1 1</scale>
              <uri>model://robotiq/meshes/s-model_articulated/collision/link_1.STL</uri>
            </mesh>
          </geometry>
          <surface>
            <contact>
              <ode/>
            </contact>
            <friction>
              <ode>
                <mu>1.1</mu>
                <mu2>1.1</mu2>
              </ode>
            </friction>
            <bounce/>
          </surface>
          <max_contacts>10</max_contacts>
        </collision>
        <visual name='l_finger_1_link_1_visual'>
          <pose>0 0.05717 0 0 -0 1.5708</pose>
          <geometry>
            <mesh>
              <scale>1 1 1</scale>
              <uri>model://robotiq/meshes/s-model_articulated/visual/link_1.STL</uri>
            </mesh>
          </geometry>
        </visual>
        <gravity>1</gravity>
        <velocity_decay/>
        <self_collide>0</self_collide>
        <kinematic>0</kinematic>
      </link>
      <joint name='l_finger_1_joint_1' type='revolute'>
        <child>l_finger_1_link_1</child>
        <parent>l_finger_1_link_0</parent>
        <axis>
          <xyz>7e-06 0 -1</xyz>
          <limit>
            <lower>0</lower>
            <upper>1.2217</upper>
            <effort>60</effort>
            <velocity>-1</velocity>
          </limit>
          <dynamics>
            <damping>1</damping>
            <friction>0</friction>
            <spring_reference>0</spring_reference>
            <spring_stiffness>0</spring_stiffness>
          </dynamics>
          <use_parent_model_frame>1</use_parent_model_frame>
        </axis>
        <physics>
          <ode>
            <implicit_spring_damper>1</implicit_spring_damper>
            <cfm_damping>1</cfm_damping>
            <limit>
              <cfm>0</cfm>
              <erp>0.2</erp>
            </limit>
          </ode>
        </physics>
      </joint>
      <link name='l_finger_1_link_2'>
        <pose>0.38092 0.073983 0.0360004 3.14159 3.64903e-06 2.0922</pose>
        <inertial>
          <pose>0.00048 0.02167 0.00018 0 -0 1.5708</pose>
          <mass>0.03284</mass>
          <inertia>
            <ixx>3.48008e-06</ixx>
            <ixy>3.194e-07</ixy>
            <ixz>1.3041e-07</ixz>
            <iyy>2.24812e-05</iyy>
            <iyz>2.91e-09</iyz>
            <izz>1.98635e-05</izz>
          </inertia>
        </inertial>
        <collision name='l_finger_1_link_2_collision'>
          <pose>0 0.0381 0.0075 0 -0 1.5708</pose>
          <geometry>
            <mesh>
              <scale>1 1 1</scale>
              <uri>model://robotiq/meshes/s-model_articulated/collision/link_2.STL</uri>
            </mesh>
          </geometry>
          <surface>
            <contact>
              <ode/>
            </contact>
            <friction>
              <ode>
                <mu>1.1</mu>
                <mu2>1.1</mu2>
              </ode>
            </friction>
            <bounce/>
          </surface>
          <max_contacts>10</max_contacts>
        </collision>
        <visual name='l_finger_1_link_2_visual'>
          <pose>0 0.0381 0.0075 0 -0 1.5708</pose>
          <geometry>
            <mesh>
              <scale>1 1 1</scale>
              <uri>model://robotiq/meshes/s-model_articulated/visual/link_2.STL</uri>
            </mesh>
          </geometry>
        </visual>
        <gravity>1</gravity>
        <velocity_decay/>
        <self_collide>0</self_collide>
        <kinematic>0</kinematic>
      </link>
      <joint name='l_finger_1_joint_2' type='revolute'>
        <child>l_finger_1_link_2</child>
        <parent>l_finger_1_link_1</parent>
        <axis>
          <xyz>7e-06 0 -1</xyz>
          <limit>
            <lower>0</lower>
            <upper>1.5708</upper>
            <effort>60</effort>
            <velocity>-1</velocity>
          </limit>
          <dynamics>
            <damping>1</damping>
            <friction>0</friction>
            <spring_reference>0</spring_reference>
            <spring_stiffness>0</spring_stiffness>
          </dynamics>
          <use_parent_model_frame>1</use_parent_model_frame>
        </axis>
        <physics>
          <ode>
            <implicit_spring_damper>1</implicit_spring_damper>
            <cfm_damping>1</cfm_damping>
            <limit>
              <cfm>0</cfm>
              <erp>0.2</erp>
            </limit>
          </ode>
        </physics>
      </joint>
      <link name='l_finger_1_link_3'>
        <pose>0.414738 0.0934085 0.0360006 -3.14159 -7.34641e-06 0.00159</pose>
        <inertial>
          <pose>0.01626 0.00049 0.0002 0 -0 0</pose>
          <mass>0.03354</mass>
          <inertia>
            <ixx>3.05151e-06</ixx>
            <ixy>8.9792e-07</ixy>
            <ixz>2.49e-09</ixz>
            <iyy>1.42798e-05</iyy>
            <iyz>-1.191e-08</iyz>
            <izz>1.26413e-05</izz>
          </inertia>
        </inertial>
        <collision name='l_finger_1_link_3_collision'>
          <pose>0 0 0 0 -0 0</pose>
          <geometry>
            <mesh>
              <scale>1 1 1</scale>
              <uri>model://robotiq/meshes/s-model_articulated/collision/link_3.STL</uri>
            </mesh>
          </geometry>
          <surface>
            <contact>
              <ode/>
            </contact>
            <friction>
              <ode>
                <mu>1.1</mu>
                <mu2>1.1</mu2>
              </ode>
            </friction>
            <bounce/>
          </surface>
          <max_contacts>10</max_contacts>
        </collision>
        <visual name='l_finger_1_link_3_visual'>
          <pose>0 0 0 0 -0 0</pose>
          <geometry>
            <mesh>
              <scale>1 1 1</scale>
              <uri>model://robotiq/meshes/s-model_articulated/visual/link_3.STL</uri>
            </mesh>
          </geometry>
        </visual>
        <gravity>1</gravity>
        <velocity_decay/>
        <self_collide>0</self_collide>
        <kinematic>0</kinematic>
      </link>
      <joint name='l_finger_1_joint_3' type='revolute'>
        <child>l_finger_1_link_3</child>
        <parent>l_finger_1_link_2</parent>
        <axis>
          <xyz>7e-06 0 -1</xyz>
          <limit>
            <lower>-0.6632</lower>
            <upper>1.0471</upper>
            <effort>60</effort>
            <velocity>-1</velocity>
          </limit>
          <dynamics>
            <damping>1</damping>
            <friction>0</friction>
            <spring_reference>0</spring_reference>
            <spring_stiffness>0</spring_stiffness>
          </dynamics>
          <use_parent_model_frame>1</use_parent_model_frame>
        </axis>
        <physics>
          <ode>
            <implicit_spring_damper>1</implicit_spring_damper>
            <cfm_damping>1</cfm_damping>
            <limit>
              <cfm>0</cfm>
              <erp>0.2</erp>
            </limit>
          </ode>
        </physics>
      </joint>
      <link name='l_finger_1_link_paradistal_hinge'>
        <pose>0.414738 0.0934085 0.0460006 3.14159 3.64903e-06 2.0922</pose>
        <inertial>
          <pose>0.00548 0 0 0 -0 0</pose>
          <mass>0.00158</mass>
          <inertia>
            <ixx>1.907e-08</ixx>
            <ixy>0</ixy>
            <ixz>0</ixz>
            <iyy>1.097e-07</iyy>
            <iyz>0</iyz>
            <izz>1.261e-07</izz>
          </inertia>
        </inertial>
        <collision name='l_finger_1_link_paradistal_hinge_collision'>
          <pose>0 0 0 0 -0 0</pose>
          <geometry>
            <box>
              <size>0.02 0.02 0.002</size>
            </box>
          </geometry>
          <surface>
            <contact>
              <ode/>
            </contact>
            <friction>
              <ode>
                <mu>1.1</mu>
                <mu2>1.1</mu2>
              </ode>
            </friction>
            <bounce/>
          </surface>
          <max_contacts>10</max_contacts>
        </collision>
        <visual name='l_finger_1_link_paradistal_hinge_visual'>
          <pose>0 0 0 0 -0 0</pose>
          <geometry>
            <box>
              <size>0.02 0.02 0.002</size>
            </box>
          </geometry>
        </visual>
        <gravity>1</gravity>
        <velocity_decay/>
        <self_collide>0</self_collide>
        <kinematic>0</kinematic>
      </link>
      <joint name='l_finger_1_joint_paradistal_hinge' type='revolute'>
        <child>l_finger_1_link_paradistal_hinge</child>
        <parent>l_finger_1_link_2</parent>
        <axis>
          <xyz>7e-06 0 -1</xyz>
          <limit>
            <lower>-3.1416</lower>
            <upper>3.1416</upper>
            <effort>100</effort>
            <velocity>100</velocity>
          </limit>
          <dynamics>
            <spring_reference>0</spring_reference>
            <spring_stiffness>0</spring_stiffness>
          </dynamics>
          <use_parent_model_frame>1</use_parent_model_frame>
        </axis>
        <physics>
          <ode>
            <implicit_spring_damper>1</implicit_spring_damper>
            <cfm_damping>1</cfm_damping>
            <limit>
              <cfm>0</cfm>
              <erp>0.2</erp>
            </limit>
          </ode>
        </physics>
      </joint>
      <link name='l_finger_1_link_median_actuating_hinge'>
        <pose>0.38092 0.073983 0.0260004 3.14159 5.70778e-06 2.4622</pose>
        <inertial>
          <pose>0.0092 0.00514 0 0 -0 0</pose>
          <mass>0.00359</mass>
          <inertia>
            <ixx>2.4735e-07</ixx>
            <ixy>2.3619e-07</ixy>
            <ixz>0</ixz>
            <iyy>4.7681e-07</iyy>
            <iyz>0</iyz>
            <izz>7.1813e-07</izz>
          </inertia>
        </inertial>
        <collision name='l_finger_1_link_median_actuating_hinge_collision'>
          <pose>0 0 0 0 -0 0</pose>
          <geometry>
            <box>
              <size>0.02 0.02 0.002</size>
            </box>
          </geometry>
          <surface>
            <contact>
              <ode/>
            </contact>
            <friction>
              <ode>
                <mu>1.1</mu>
                <mu2>1.1</mu2>
              </ode>
            </friction>
            <bounce/>
          </surface>
          <max_contacts>10</max_contacts>
        </collision>
        <visual name='l_finger_1_link_median_actuating_hinge_visual'>
          <pose>0 0 0 0 -0 0</pose>
          <geometry>
            <box>
              <size>0.02 0.02 0.002</size>
            </box>
          </geometry>
        </visual>
        <gravity>1</gravity>
        <velocity_decay/>
        <self_collide>0</self_collide>
        <kinematic>0</kinematic>
      </link>
      <joint name='l_finger_1_joint_median_actuating_hinge' type='revolute'>
        <child>l_finger_1_link_median_actuating_hinge</child>
        <parent>l_finger_1_link_1</parent>
        <axis>
          <xyz>7e-06 0 -1</xyz>
          <limit>
            <lower>-3.1416</lower>
            <upper>3.1416</upper>
            <effort>100</effort>
            <velocity>100</velocity>
          </limit>
          <dynamics>
            <spring_reference>0</spring_reference>
            <spring_stiffness>0</spring_stiffness>
          </dynamics>
          <use_parent_model_frame>1</use_parent_model_frame>
        </axis>
        <physics>
          <ode>
            <implicit_spring_damper>1</implicit_spring_damper>
            <cfm_damping>1</cfm_damping>
            <limit>
              <cfm>0</cfm>
              <erp>0.2</erp>
            </limit>
          </ode>
        </physics>
      </joint>
      <link name='l_finger_1_link_median_bar'>
        <pose>0.377804 0.095987 0.0260003 3.14159 -7.27545e-06 0.14069</pose>
        <inertial>
          <pose>0.01905 -0.00107 0 0 -0 0</pose>
          <mass>0.00538</mass>
          <inertia>
            <ixx>6.639e-08</ixx>
            <ixy>-1.0996e-07</ixy>
            <ixz>9.4e-10</ixz>
            <iyy>3.05318e-06</iyy>
            <iyz>0</iyz>
            <izz>3.04657e-06</izz>
          </inertia>
        </inertial>
        <collision name='l_finger_1_link_median_bar_collision'>
          <pose>0.01905 0 0 0 -0 0</pose>
          <geometry>
            <box>
              <size>0.0381 0.0075 0.002</size>
            </box>
          </geometry>
          <surface>
            <contact>
              <ode/>
            </contact>
            <friction>
              <ode>
                <mu>1.1</mu>
                <mu2>1.1</mu2>
              </ode>
            </friction>
            <bounce/>
          </surface>
          <max_contacts>10</max_contacts>
        </collision>
        <visual name='l_finger_1_link_median_bar_visual'>
          <pose>0.01905 0 0 0 -0 0</pose>
          <geometry>
            <box>
              <size>0.0381 0.0075 0.002</size>
            </box>
          </geometry>
        </visual>
        <gravity>1</gravity>
        <velocity_decay/>
        <self_collide>0</self_collide>
        <kinematic>0</kinematic>
      </link>
      <joint name='l_finger_1_joint_median_actuating_hinge_median_bar' type='revolute'>
        <child>l_finger_1_link_median_bar</child>
        <parent>l_finger_1_link_median_actuating_hinge</parent>
        <axis>
          <xyz>7e-06 0 -1</xyz>
          <limit>
            <lower>-3.1416</lower>
            <upper>3.1416</upper>
            <effort>100</effort>
            <velocity>100</velocity>
          </limit>
          <dynamics>
            <spring_reference>0</spring_reference>
            <spring_stiffness>0</spring_stiffness>
          </dynamics>
          <use_parent_model_frame>1</use_parent_model_frame>
        </axis>
        <physics>
          <ode>
            <implicit_spring_damper>1</implicit_spring_damper>
            <cfm_damping>1</cfm_damping>
            <limit>
              <cfm>0</cfm>
              <erp>0.2</erp>
            </limit>
          </ode>
        </physics>
      </joint>
      <link name='l_finger_1_link_paramedian_hinge'>
        <pose>0.38092 0.073983 0.0460004 3.14159 3.64903e-06 2.0922</pose>
        <inertial>
          <pose>-0.01025 0.00046 0 0 -0 0</pose>
          <mass>0.00276</mass>
          <inertia>
            <ixx>4.213e-08</ixx>
            <ixy>-1.491e-08</ixy>
            <ixz>0</ixz>
            <iyy>5.0258e-07</iyy>
            <iyz>0</iyz>
            <izz>5.4007e-07</izz>
          </inertia>
        </inertial>
        <collision name='l_finger_1_link_paramedian_hinge_collision'>
          <pose>0 0 0 0 -0 0</pose>
          <geometry>
            <box>
              <size>0.02 0.02 0.002</size>
            </box>
          </geometry>
          <surface>
            <contact>
              <ode/>
            </contact>
            <friction>
              <ode>
                <mu>1.1</mu>
                <mu2>1.1</mu2>
              </ode>
            </friction>
            <bounce/>
          </surface>
          <max_contacts>10</max_contacts>
        </collision>
        <visual name='l_finger_1_link_paramedian_hinge_visual'>
          <pose>0 0 0 0 -0 0</pose>
          <geometry>
            <box>
              <size>0.02 0.02 0.002</size>
            </box>
          </geometry>
        </visual>
        <gravity>1</gravity>
        <velocity_decay/>
        <self_collide>0</self_collide>
        <kinematic>0</kinematic>
      </link>
      <joint name='l_finger_1_joint_paramedian_hinge' type='revolute'>
        <child>l_finger_1_link_paramedian_hinge</child>
        <parent>l_finger_1_link_1</parent>
        <axis>
          <xyz>7e-06 0 -1</xyz>
          <limit>
            <lower>-3.1416</lower>
            <upper>3.1416</upper>
            <effort>100</effort>
            <velocity>100</velocity>
          </limit>
          <dynamics>
            <spring_reference>0</spring_reference>
            <spring_stiffness>0</spring_stiffness>
          </dynamics>
          <use_parent_model_frame>1</use_parent_model_frame>
        </axis>
        <physics>
          <ode>
            <implicit_spring_damper>1</implicit_spring_damper>
            <cfm_damping>1</cfm_damping>
            <limit>
              <cfm>0</cfm>
              <erp>0.2</erp>
            </limit>
          </ode>
        </physics>
      </joint>
      <link name='l_finger_1_link_median_bar_underactuated'>
        <pose>0.377661 0.0862613 0.0460003 3.14159 -6.37609e-06 0.52139</pose>
        <inertial>
          <pose>0.01905 -0.00107 0 0 -0 0</pose>
          <mass>0.00538</mass>
          <inertia>
            <ixx>6.639e-08</ixx>
            <ixy>-1.0996e-07</ixy>
            <ixz>-9.4e-10</ixz>
            <iyy>3.05318e-06</iyy>
            <iyz>0</iyz>
            <izz>3.04657e-06</izz>
          </inertia>
        </inertial>
        <collision name='l_finger_1_link_median_bar_underactuated_collision'>
          <pose>0.01905 0 0 0 -0 0</pose>
          <geometry>
            <box>
              <size>0.0381 0.0075 0.002</size>
            </box>
          </geometry>
          <surface>
            <contact>
              <ode/>
            </contact>
            <friction>
              <ode>
                <mu>1.1</mu>
                <mu2>1.1</mu2>
              </ode>
            </friction>
            <bounce/>
          </surface>
          <max_contacts>10</max_contacts>
        </collision>
        <visual name='l_finger_1_link_median_bar_underactuated_visual'>
          <pose>0.01905 0 0 0 -0 0</pose>
          <geometry>
            <box>
              <size>0.0381 0.0075 0.002</size>
            </box>
          </geometry>
        </visual>
        <gravity>1</gravity>
        <velocity_decay/>
        <self_collide>0</self_collide>
        <kinematic>0</kinematic>
      </link>
      <joint name='l_finger_1_joint_paramedian_hinge_median_bar_underactuated' type='revolute'>
        <child>l_finger_1_link_median_bar_underactuated</child>
        <parent>l_finger_1_link_paramedian_hinge</parent>
        <axis>
          <xyz>7e-06 0 -1</xyz>
          <limit>
            <lower>-3.1416</lower>
            <upper>3.1416</upper>
            <effort>100</effort>
            <velocity>100</velocity>
          </limit>
          <dynamics>
            <spring_reference>0</spring_reference>
            <spring_stiffness>0</spring_stiffness>
          </dynamics>
          <use_parent_model_frame>1</use_parent_model_frame>
        </axis>
        <physics>
          <ode>
            <implicit_spring_damper>1</implicit_spring_damper>
            <cfm_damping>1</cfm_damping>
            <limit>
              <cfm>0</cfm>
              <erp>0.2</erp>
            </limit>
          </ode>
        </physics>
      </joint>
      <link name='l_finger_1_link_paraproximal_actuating_hinge'>
        <pose>0.331364 0.045517 0.046 3.14159 3.64903e-06 2.0922</pose>
        <inertial>
          <pose>0.0064 0 0 0 -0 0</pose>
          <mass>0.00362</mass>
          <inertia>
            <ixx>1.2043e-07</ixx>
            <ixy>0</ixy>
            <ixz>0</ixz>
            <iyy>5.3588e-07</iyy>
            <iyz>0</iyz>
            <izz>6.5322e-07</izz>
          </inertia>
        </inertial>
        <collision name='l_finger_1_link_paraproximal_actuating_hinge_collision'>
          <pose>0.01143 0 0 0 -0 0</pose>
          <geometry>
            <box>
              <size>0.02286 0.0075 0.002</size>
            </box>
          </geometry>
          <surface>
            <contact>
              <ode/>
            </contact>
            <friction>
              <ode>
                <mu>1.1</mu>
                <mu2>1.1</mu2>
              </ode>
            </friction>
            <bounce/>
          </surface>
          <max_contacts>10</max_contacts>
        </collision>
        <visual name='l_finger_1_link_paraproximal_actuating_hinge_visual'>
          <pose>0.01143 0 0 0 -0 0</pose>
          <geometry>
            <box>
              <size>0.02286 0.0075 0.002</size>
            </box>
          </geometry>
        </visual>
        <gravity>1</gravity>
        <velocity_decay/>
        <self_collide>0</self_collide>
        <kinematic>0</kinematic>
      </link>
      <joint name='l_finger_1_joint_paraproximal_actuating_hinge' type='revolute'>
        <child>l_finger_1_link_paraproximal_actuating_hinge</child>
        <parent>l_finger_1_link_0</parent>
        <axis>
          <xyz>7e-06 0 -1</xyz>
          <limit>
            <lower>-3.1416</lower>
            <upper>3.1416</upper>
            <effort>100</effort>
            <velocity>100</velocity>
          </limit>
          <dynamics>
            <spring_reference>0</spring_reference>
            <spring_stiffness>0</spring_stiffness>
          </dynamics>
          <use_parent_model_frame>1</use_parent_model_frame>
        </axis>
        <physics>
          <ode>
            <implicit_spring_damper>1</implicit_spring_damper>
            <cfm_damping>1</cfm_damping>
            <limit>
              <cfm>0</cfm>
              <erp>0.2</erp>
            </limit>
          </ode>
        </physics>
      </joint>
      <link name='l_finger_1_link_paraproximal_bar'>
        <pose>0.319977 0.0653395 0.0459999 3.14159 -6.37316e-06 0.52219</pose>
        <inertial>
          <pose>0.02858 -0.00129 0 0 -0 0</pose>
          <mass>0.00732</mass>
          <inertia>
            <ixx>9.065e-08</ixx>
            <ixy>-2.7047e-07</ixy>
            <ixz>1.42e-09</ixz>
            <iyy>8.78034e-06</iyy>
            <iyz>0</iyz>
            <izz>8.77558e-06</izz>
          </inertia>
        </inertial>
        <collision name='l_finger_1_link_paraproximal_bar_collision'>
          <pose>0.02885 0 0 0 -0 0</pose>
          <geometry>
            <box>
              <size>0.0577 0.0075 0.002</size>
            </box>
          </geometry>
          <surface>
            <contact>
              <ode/>
            </contact>
            <friction>
              <ode>
                <mu>1.1</mu>
                <mu2>1.1</mu2>
              </ode>
            </friction>
            <bounce/>
          </surface>
          <max_contacts>10</max_contacts>
        </collision>
        <visual name='l_finger_1_link_paraproximal_bar_visual'>
          <pose>0.02885 0 0 0 -0 0</pose>
          <geometry>
            <box>
              <size>0.0577 0.0075 0.002</size>
            </box>
          </geometry>
        </visual>
        <gravity>1</gravity>
        <velocity_decay/>
        <self_collide>0</self_collide>
        <kinematic>0</kinematic>
      </link>
      <joint name='l_finger_1_joint_paraproximal_bar' type='revolute'>
        <child>l_finger_1_link_paraproximal_bar</child>
        <parent>l_finger_1_link_paraproximal_actuating_hinge</parent>
        <axis>
          <xyz>7e-06 0 -1</xyz>
          <limit>
            <lower>-3.1416</lower>
            <upper>3.1416</upper>
            <effort>100</effort>
            <velocity>100</velocity>
          </limit>
          <dynamics>
            <spring_reference>0</spring_reference>
            <spring_stiffness>0</spring_stiffness>
          </dynamics>
          <use_parent_model_frame>1</use_parent_model_frame>
        </axis>
        <physics>
          <ode>
            <implicit_spring_damper>1</implicit_spring_damper>
            <cfm_damping>1</cfm_damping>
            <limit>
              <cfm>0</cfm>
              <erp>0.2</erp>
            </limit>
          </ode>
        </physics>
      </joint>
      <link name='l_finger_1_link_proximal_actuating_hinge'>
        <pose>0.331364 0.045517 0.026 3.14159 3.64903e-06 2.0922</pose>
        <inertial>
          <pose>0.0012 -0.00162 -0.00161 0 -0 0</pose>
          <mass>0.02647</mass>
          <inertia>
            <ixx>1.56447e-06</ixx>
            <ixy>2.36226e-07</ixy>
            <ixz>-1.4862e-07</ixz>
            <iyy>2.21068e-06</iyy>
            <iyz>-1.4369e-07</iyz>
            <izz>3.23175e-06</izz>
          </inertia>
        </inertial>
        <collision name='l_finger_1_link_proximal_actuating_hinge_collision'>
          <pose>0.01429 0 0 0 -0 0</pose>
          <geometry>
            <box>
              <size>0.02858 0.0075 0.002</size>
            </box>
          </geometry>
          <surface>
            <contact>
              <ode/>
            </contact>
            <friction>
              <ode>
                <mu>1.1</mu>
                <mu2>1.1</mu2>
              </ode>
            </friction>
            <bounce/>
          </surface>
          <max_contacts>10</max_contacts>
        </collision>
        <visual name='l_finger_1_link_proximal_actuating_hinge_visual'>
          <pose>0.01429 0 0 0 -0 0</pose>
          <geometry>
            <box>
              <size>0.02858 0.0075 0.002</size>
            </box>
          </geometry>
        </visual>
        <gravity>1</gravity>
        <velocity_decay/>
        <self_collide>0</self_collide>
        <kinematic>0</kinematic>
      </link>
      <joint name='l_finger_1_joint_proximal_actuating_hinge' type='revolute'>
        <child>l_finger_1_link_proximal_actuating_hinge</child>
        <parent>l_finger_1_link_0</parent>
        <axis>
          <xyz>7e-06 0 -1</xyz>
          <limit>
            <lower>-3.1416</lower>
            <upper>3.1416</upper>
            <effort>100</effort>
            <velocity>100</velocity>
          </limit>
          <dynamics>
            <spring_reference>0</spring_reference>
            <spring_stiffness>0</spring_stiffness>
          </dynamics>
          <use_parent_model_frame>1</use_parent_model_frame>
        </axis>
        <physics>
          <ode>
            <implicit_spring_damper>1</implicit_spring_damper>
            <cfm_damping>1</cfm_damping>
            <limit>
              <cfm>0</cfm>
              <erp>0.2</erp>
            </limit>
          </ode>
        </physics>
      </joint>
      <link name='l_finger_1_link_proximal_actuating_bar'>
        <pose>0.317128 0.0702994 0.0259999 3.14159 -7.15462e-06 0.23059</pose>
        <inertial>
          <pose>0.02699 -0.00122 0 0 -0 0</pose>
          <mass>0.00659</mass>
          <inertia>
            <ixx>8.348e-08</ixx>
            <ixy>-2.179e-07</ixy>
            <ixz>1.34e-09</ixz>
            <iyy>7.19076e-06</iyy>
            <iyz>0</iyz>
            <izz>7.18272e-06</izz>
          </inertia>
        </inertial>
        <collision name='l_finger_1_link_proximal_actuating_bar_collision'>
          <pose>0.026789 0 0 0 -0 0</pose>
          <geometry>
            <box>
              <size>0.05398 0.0075 0.002</size>
            </box>
          </geometry>
          <surface>
            <contact>
              <ode/>
            </contact>
            <friction>
              <ode>
                <mu>1.1</mu>
                <mu2>1.1</mu2>
              </ode>
            </friction>
            <bounce/>
          </surface>
          <max_contacts>10</max_contacts>
        </collision>
        <visual name='l_finger_1_link_proximal_actuating_bar_visual'>
          <pose>0.026789 0 0 0 -0 0</pose>
          <geometry>
            <box>
              <size>0.05398 0.0075 0.002</size>
            </box>
          </geometry>
        </visual>
        <gravity>1</gravity>
        <velocity_decay/>
        <self_collide>0</self_collide>
        <kinematic>0</kinematic>
      </link>
      <joint name='l_finger_1_joint_proximal_actuating_bar' type='revolute'>
        <child>l_finger_1_link_proximal_actuating_bar</child>
        <parent>l_finger_1_link_proximal_actuating_hinge</parent>
        <axis>
          <xyz>7e-06 0 -1</xyz>
          <limit>
            <lower>-3.1416</lower>
            <upper>3.1416</upper>
            <effort>100</effort>
            <velocity>100</velocity>
          </limit>
          <dynamics>
            <spring_reference>0</spring_reference>
            <spring_stiffness>0</spring_stiffness>
          </dynamics>
          <use_parent_model_frame>1</use_parent_model_frame>
        </axis>
        <physics>
          <ode>
            <implicit_spring_damper>1</implicit_spring_damper>
            <cfm_damping>1</cfm_damping>
            <limit>
              <cfm>0</cfm>
              <erp>0.2</erp>
            </limit>
          </ode>
        </physics>
      </joint>
      <link name='l_finger_2_link_0'>
        <pose>0.331364 0.045517 -0.036 3.14159 -7.34641e-06 0.00159</pose>
        <inertial>
          <pose>-0.01 0 0 0 -0 0</pose>
          <mass>0.1</mass>
          <inertia>
            <ixx>1.8e-05</ixx>
            <ixy>0</ixy>
            <ixz>0</ixz>
            <iyy>2.5e-05</iyy>
            <iyz>0</iyz>
            <izz>2.5e-05</izz>
          </inertia>
        </inertial>
        <collision name='l_finger_2_link_0_collision'>
          <pose>0 0 0 0 -0 0</pose>
          <geometry>
            <mesh>
              <scale>1 1 1</scale>
              <uri>model://robotiq/meshes/s-model_articulated/collision/link_0.STL</uri>
            </mesh>
          </geometry>
          <surface>
            <contact>
              <ode/>
            </contact>
            <friction>
              <ode>
                <mu>1.1</mu>
                <mu2>1.1</mu2>
              </ode>
            </friction>
            <bounce/>
          </surface>
          <max_contacts>10</max_contacts>
        </collision>
        <visual name='l_finger_2_link_0_visual'>
          <pose>0 0 0 0 -0 0</pose>
          <geometry>
            <mesh>
              <scale>1 1 1</scale>
              <uri>model://robotiq/meshes/s-model_articulated/visual/link_0.STL</uri>
            </mesh>
          </geometry>
        </visual>
        <gravity>1</gravity>
        <velocity_decay/>
        <self_collide>0</self_collide>
        <kinematic>0</kinematic>
      </link>
      <joint name='l_palm_finger_2_joint' type='revolute'>
        <child>l_finger_2_link_0</child>
        <parent>base_link</parent>
        <axis>
          <xyz>0.001593 -0.999999 0</xyz>
          <limit>
            <lower>-0.2967</lower>
            <upper>0.2967</upper>
            <effort>60</effort>
            <velocity>-1</velocity>
          </limit>
          <dynamics>
            <damping>1</damping>
            <friction>0</friction>
            <spring_reference>0</spring_reference>
            <spring_stiffness>0</spring_stiffness>
          </dynamics>
          <use_parent_model_frame>1</use_parent_model_frame>
        </axis>
        <physics>
          <ode>
            <implicit_spring_damper>1</implicit_spring_damper>
            <cfm_damping>1</cfm_damping>
            <limit>
              <cfm>0</cfm>
              <erp>0.2</erp>
            </limit>
          </ode>
        </physics>
      </joint>
      <link name='l_finger_2_link_1'>
        <pose>0.331364 0.045517 -0.036 3.14159 3.64903e-06 2.0922</pose>
        <inertial>
          <pose>0.00053 0.03218 0 0 -0 1.5708</pose>
          <mass>0.047</mass>
          <inertia>
            <ixx>4.99332e-06</ixx>
            <ixy>9.1312e-07</ixy>
            <ixz>-1.2e-09</ixz>
            <iyy>6.43453e-05</iyy>
            <iyz>-7e-11</iyz>
            <izz>6.06192e-05</izz>
          </inertia>
        </inertial>
        <collision name='l_finger_2_link_1_collision'>
          <pose>0 0.05717 0 0 -0 1.5708</pose>
          <geometry>
            <mesh>
              <scale>1 1 1</scale>
              <uri>model://robotiq/meshes/s-model_articulated/collision/link_1.STL</uri>
            </mesh>
          </geometry>
          <surface>
            <contact>
              <ode/>
            </contact>
            <friction>
              <ode>
                <mu>1.1</mu>
                <mu2>1.1</mu2>
              </ode>
            </friction>
            <bounce/>
          </surface>
          <max_contacts>10</max_contacts>
        </collision>
        <visual name='l_finger_2_link_1_visual'>
          <pose>0 0.05717 0 0 -0 1.5708</pose>
          <geometry>
            <mesh>
              <scale>1 1 1</scale>
              <uri>model://robotiq/meshes/s-model_articulated/visual/link_1.STL</uri>
            </mesh>
          </geometry>
        </visual>
        <gravity>1</gravity>
        <velocity_decay/>
        <self_collide>0</self_collide>
        <kinematic>0</kinematic>
      </link>
      <joint name='l_finger_2_joint_1' type='revolute'>
        <child>l_finger_2_link_1</child>
        <parent>l_finger_2_link_0</parent>
        <axis>
          <xyz>7e-06 0 -1</xyz>
          <limit>
            <lower>0</lower>
            <upper>1.2217</upper>
            <effort>60</effort>
            <velocity>-1</velocity>
          </limit>
          <dynamics>
            <damping>1</damping>
            <friction>0</friction>
            <spring_reference>0</spring_reference>
            <spring_stiffness>0</spring_stiffness>
          </dynamics>
          <use_parent_model_frame>1</use_parent_model_frame>
        </axis>
        <physics>
          <ode>
            <implicit_spring_damper>1</implicit_spring_damper>
            <cfm_damping>1</cfm_damping>
            <limit>
              <cfm>0</cfm>
              <erp>0.2</erp>
            </limit>
          </ode>
        </physics>
      </joint>
      <link name='l_finger_2_link_2'>
        <pose>0.38092 0.073983 -0.0359996 3.14159 3.64903e-06 2.0922</pose>
        <inertial>
          <pose>0.00048 0.02167 0.00018 0 -0 1.5708</pose>
          <mass>0.03284</mass>
          <inertia>
            <ixx>3.48008e-06</ixx>
            <ixy>3.194e-07</ixy>
            <ixz>1.3041e-07</ixz>
            <iyy>2.24812e-05</iyy>
            <iyz>2.91e-09</iyz>
            <izz>1.98635e-05</izz>
          </inertia>
        </inertial>
        <collision name='l_finger_2_link_2_collision'>
          <pose>0 0.0381 0.0075 0 -0 1.5708</pose>
          <geometry>
            <mesh>
              <scale>1 1 1</scale>
              <uri>model://robotiq/meshes/s-model_articulated/collision/link_2.STL</uri>
            </mesh>
          </geometry>
          <surface>
            <contact>
              <ode/>
            </contact>
            <friction>
              <ode>
                <mu>1.1</mu>
                <mu2>1.1</mu2>
              </ode>
            </friction>
            <bounce/>
          </surface>
          <max_contacts>10</max_contacts>
        </collision>
        <visual name='l_finger_2_link_2_visual'>
          <pose>0 0.0381 0.0075 0 -0 1.5708</pose>
          <geometry>
            <mesh>
              <scale>1 1 1</scale>
              <uri>model://robotiq/meshes/s-model_articulated/visual/link_2.STL</uri>
            </mesh>
          </geometry>
        </visual>
        <gravity>1</gravity>
        <velocity_decay/>
        <self_collide>0</self_collide>
        <kinematic>0</kinematic>
      </link>
      <joint name='l_finger_2_joint_2' type='revolute'>
        <child>l_finger_2_link_2</child>
        <parent>l_finger_2_link_1</parent>
        <axis>
          <xyz>7e-06 0 -1</xyz>
          <limit>
            <lower>0</lower>
            <upper>1.5708</upper>
            <effort>60</effort>
            <velocity>-1</velocity>
          </limit>
          <dynamics>
            <damping>1</damping>
            <friction>0</friction>
            <spring_reference>0</spring_reference>
            <spring_stiffness>0</spring_stiffness>
          </dynamics>
          <use_parent_model_frame>1</use_parent_model_frame>
        </axis>
        <physics>
          <ode>
            <implicit_spring_damper>1</implicit_spring_damper>
            <cfm_damping>1</cfm_damping>
            <limit>
              <cfm>0</cfm>
              <erp>0.2</erp>
            </limit>
          </ode>
        </physics>
      </joint>
      <link name='l_finger_2_link_3'>
        <pose>0.414738 0.0934085 -0.0359994 -3.14159 -7.34641e-06 0.00159</pose>
        <inertial>
          <pose>0.01626 0.00049 0.0002 0 -0 0</pose>
          <mass>0.03354</mass>
          <inertia>
            <ixx>3.05151e-06</ixx>
            <ixy>8.9792e-07</ixy>
            <ixz>2.49e-09</ixz>
            <iyy>1.42798e-05</iyy>
            <iyz>-1.191e-08</iyz>
            <izz>1.26413e-05</izz>
          </inertia>
        </inertial>
        <collision name='l_finger_2_link_3_collision'>
          <pose>0 0 0 0 -0 0</pose>
          <geometry>
            <mesh>
              <scale>1 1 1</scale>
              <uri>model://robotiq/meshes/s-model_articulated/collision/link_3.STL</uri>
            </mesh>
          </geometry>
          <surface>
            <contact>
              <ode/>
            </contact>
            <friction>
              <ode>
                <mu>1.1</mu>
                <mu2>1.1</mu2>
              </ode>
            </friction>
            <bounce/>
          </surface>
          <max_contacts>10</max_contacts>
        </collision>
        <visual name='l_finger_2_link_3_visual'>
          <pose>0 0 0 0 -0 0</pose>
          <geometry>
            <mesh>
              <scale>1 1 1</scale>
              <uri>model://robotiq/meshes/s-model_articulated/visual/link_3.STL</uri>
            </mesh>
          </geometry>
        </visual>
        <gravity>1</gravity>
        <velocity_decay/>
        <self_collide>0</self_collide>
        <kinematic>0</kinematic>
      </link>
      <joint name='l_finger_2_joint_3' type='revolute'>
        <child>l_finger_2_link_3</child>
        <parent>l_finger_2_link_2</parent>
        <axis>
          <xyz>7e-06 0 -1</xyz>
          <limit>
            <lower>-0.6632</lower>
            <upper>1.0471</upper>
            <effort>60</effort>
            <velocity>-1</velocity>
          </limit>
          <dynamics>
            <damping>1</damping>
            <friction>0</friction>
            <spring_reference>0</spring_reference>
            <spring_stiffness>0</spring_stiffness>
          </dynamics>
          <use_parent_model_frame>1</use_parent_model_frame>
        </axis>
        <physics>
          <ode>
            <implicit_spring_damper>1</implicit_spring_damper>
            <cfm_damping>1</cfm_damping>
            <limit>
              <cfm>0</cfm>
              <erp>0.2</erp>
            </limit>
          </ode>
        </physics>
      </joint>
      <link name='l_finger_2_link_paradistal_hinge'>
        <pose>0.414738 0.0934085 -0.0259994 3.14159 3.64903e-06 2.0922</pose>
        <inertial>
          <pose>0.00548 0 0 0 -0 0</pose>
          <mass>0.00158</mass>
          <inertia>
            <ixx>1.907e-08</ixx>
            <ixy>0</ixy>
            <ixz>0</ixz>
            <iyy>1.097e-07</iyy>
            <iyz>0</iyz>
            <izz>1.261e-07</izz>
          </inertia>
        </inertial>
        <collision name='l_finger_2_link_paradistal_hinge_collision'>
          <pose>0 0 0 0 -0 0</pose>
          <geometry>
            <box>
              <size>0.02 0.02 0.002</size>
            </box>
          </geometry>
          <surface>
            <contact>
              <ode/>
            </contact>
            <friction>
              <ode>
                <mu>1.1</mu>
                <mu2>1.1</mu2>
              </ode>
            </friction>
            <bounce/>
          </surface>
          <max_contacts>10</max_contacts>
        </collision>
        <visual name='l_finger_2_link_paradistal_hinge_visual'>
          <pose>0 0 0 0 -0 0</pose>
          <geometry>
            <box>
              <size>0.02 0.02 0.002</size>
            </box>
          </geometry>
        </visual>
        <gravity>1</gravity>
        <velocity_decay/>
        <self_collide>0</self_collide>
        <kinematic>0</kinematic>
      </link>
      <joint name='l_finger_2_joint_paradistal_hinge' type='revolute'>
        <child>l_finger_2_link_paradistal_hinge</child>
        <parent>l_finger_2_link_2</parent>
        <axis>
          <xyz>7e-06 0 -1</xyz>
          <limit>
            <lower>-3.1416</lower>
            <upper>3.1416</upper>
            <effort>100</effort>
            <velocity>100</velocity>
          </limit>
          <dynamics>
            <spring_reference>0</spring_reference>
            <spring_stiffness>0</spring_stiffness>
          </dynamics>
          <use_parent_model_frame>1</use_parent_model_frame>
        </axis>
        <physics>
          <ode>
            <implicit_spring_damper>1</implicit_spring_damper>
            <cfm_damping>1</cfm_damping>
            <limit>
              <cfm>0</cfm>
              <erp>0.2</erp>
            </limit>
          </ode>
        </physics>
      </joint>
      <link name='l_finger_2_link_median_actuating_hinge'>
        <pose>0.38092 0.073983 -0.0459996 3.14159 5.70778e-06 2.4622</pose>
        <inertial>
          <pose>0.0092 0.00514 0 0 -0 0</pose>
          <mass>0.00359</mass>
          <inertia>
            <ixx>2.4735e-07</ixx>
            <ixy>2.3619e-07</ixy>
            <ixz>0</ixz>
            <iyy>4.7681e-07</iyy>
            <iyz>0</iyz>
            <izz>7.1813e-07</izz>
          </inertia>
        </inertial>
        <collision name='l_finger_2_link_median_actuating_hinge_collision'>
          <pose>0 0 0 0 -0 0</pose>
          <geometry>
            <box>
              <size>0.02 0.02 0.002</size>
            </box>
          </geometry>
          <surface>
            <contact>
              <ode/>
            </contact>
            <friction>
              <ode>
                <mu>1.1</mu>
                <mu2>1.1</mu2>
              </ode>
            </friction>
            <bounce/>
          </surface>
          <max_contacts>10</max_contacts>
        </collision>
        <visual name='l_finger_2_link_median_actuating_hinge_visual'>
          <pose>0 0 0 0 -0 0</pose>
          <geometry>
            <box>
              <size>0.02 0.02 0.002</size>
            </box>
          </geometry>
        </visual>
        <gravity>1</gravity>
        <velocity_decay/>
        <self_collide>0</self_collide>
        <kinematic>0</kinematic>
      </link>
      <joint name='l_finger_2_joint_median_actuating_hinge' type='revolute'>
        <child>l_finger_2_link_median_actuating_hinge</child>
        <parent>l_finger_2_link_1</parent>
        <axis>
          <xyz>7e-06 0 -1</xyz>
          <limit>
            <lower>-3.1416</lower>
            <upper>3.1416</upper>
            <effort>100</effort>
            <velocity>100</velocity>
          </limit>
          <dynamics>
            <spring_reference>0</spring_reference>
            <spring_stiffness>0</spring_stiffness>
          </dynamics>
          <use_parent_model_frame>1</use_parent_model_frame>
        </axis>
        <physics>
          <ode>
            <implicit_spring_damper>1</implicit_spring_damper>
            <cfm_damping>1</cfm_damping>
            <limit>
              <cfm>0</cfm>
              <erp>0.2</erp>
            </limit>
          </ode>
        </physics>
      </joint>
      <link name='l_finger_2_link_median_bar'>
        <pose>0.377804 0.095987 -0.0459997 3.14159 -7.27545e-06 0.14069</pose>
        <inertial>
          <pose>0.01905 -0.00107 0 0 -0 0</pose>
          <mass>0.00538</mass>
          <inertia>
            <ixx>6.639e-08</ixx>
            <ixy>-1.0996e-07</ixy>
            <ixz>9.4e-10</ixz>
            <iyy>3.05318e-06</iyy>
            <iyz>0</iyz>
            <izz>3.04657e-06</izz>
          </inertia>
        </inertial>
        <collision name='l_finger_2_link_median_bar_collision'>
          <pose>0.01905 0 0 0 -0 0</pose>
          <geometry>
            <box>
              <size>0.0381 0.0075 0.002</size>
            </box>
          </geometry>
          <surface>
            <contact>
              <ode/>
            </contact>
            <friction>
              <ode>
                <mu>1.1</mu>
                <mu2>1.1</mu2>
              </ode>
            </friction>
            <bounce/>
          </surface>
          <max_contacts>10</max_contacts>
        </collision>
        <visual name='l_finger_2_link_median_bar_visual'>
          <pose>0.01905 0 0 0 -0 0</pose>
          <geometry>
            <box>
              <size>0.0381 0.0075 0.002</size>
            </box>
          </geometry>
        </visual>
        <gravity>1</gravity>
        <velocity_decay/>
        <self_collide>0</self_collide>
        <kinematic>0</kinematic>
      </link>
      <joint name='l_finger_2_joint_median_actuating_hinge_median_bar' type='revolute'>
        <child>l_finger_2_link_median_bar</child>
        <parent>l_finger_2_link_median_actuating_hinge</parent>
        <axis>
          <xyz>7e-06 0 -1</xyz>
          <limit>
            <lower>-3.1416</lower>
            <upper>3.1416</upper>
            <effort>100</effort>
            <velocity>100</velocity>
          </limit>
          <dynamics>
            <spring_reference>0</spring_reference>
            <spring_stiffness>0</spring_stiffness>
          </dynamics>
          <use_parent_model_frame>1</use_parent_model_frame>
        </axis>
        <physics>
          <ode>
            <implicit_spring_damper>1</implicit_spring_damper>
            <cfm_damping>1</cfm_damping>
            <limit>
              <cfm>0</cfm>
              <erp>0.2</erp>
            </limit>
          </ode>
        </physics>
      </joint>
      <link name='l_finger_2_link_paramedian_hinge'>
        <pose>0.38092 0.073983 -0.0259996 3.14159 3.64903e-06 2.0922</pose>
        <inertial>
          <pose>-0.01025 0.00046 0 0 -0 0</pose>
          <mass>0.00276</mass>
          <inertia>
            <ixx>4.213e-08</ixx>
            <ixy>-1.491e-08</ixy>
            <ixz>0</ixz>
            <iyy>5.0258e-07</iyy>
            <iyz>0</iyz>
            <izz>5.4007e-07</izz>
          </inertia>
        </inertial>
        <collision name='l_finger_2_link_paramedian_hinge_collision'>
          <pose>0 0 0 0 -0 0</pose>
          <geometry>
            <box>
              <size>0.02 0.02 0.002</size>
            </box>
          </geometry>
          <surface>
            <contact>
              <ode/>
            </contact>
            <friction>
              <ode>
                <mu>1.1</mu>
                <mu2>1.1</mu2>
              </ode>
            </friction>
            <bounce/>
          </surface>
          <max_contacts>10</max_contacts>
        </collision>
        <visual name='l_finger_2_link_paramedian_hinge_visual'>
          <pose>0 0 0 0 -0 0</pose>
          <geometry>
            <box>
              <size>0.02 0.02 0.002</size>
            </box>
          </geometry>
        </visual>
        <gravity>1</gravity>
        <velocity_decay/>
        <self_collide>0</self_collide>
        <kinematic>0</kinematic>
      </link>
      <joint name='l_finger_2_joint_paramedian_hinge' type='revolute'>
        <child>l_finger_2_link_paramedian_hinge</child>
        <parent>l_finger_2_link_1</parent>
        <axis>
          <xyz>7e-06 0 -1</xyz>
          <limit>
            <lower>-3.1416</lower>
            <upper>3.1416</upper>
            <effort>100</effort>
            <velocity>100</velocity>
          </limit>
          <dynamics>
            <spring_reference>0</spring_reference>
            <spring_stiffness>0</spring_stiffness>
          </dynamics>
          <use_parent_model_frame>1</use_parent_model_frame>
        </axis>
        <physics>
          <ode>
            <implicit_spring_damper>1</implicit_spring_damper>
            <cfm_damping>1</cfm_damping>
            <limit>
              <cfm>0</cfm>
              <erp>0.2</erp>
            </limit>
          </ode>
        </physics>
      </joint>
      <link name='l_finger_2_link_median_bar_underactuated'>
        <pose>0.377661 0.0862613 -0.0259997 3.14159 -6.37609e-06 0.52139</pose>
        <inertial>
          <pose>0.01905 -0.00107 0 0 -0 0</pose>
          <mass>0.00538</mass>
          <inertia>
            <ixx>6.639e-08</ixx>
            <ixy>-1.0996e-07</ixy>
            <ixz>-9.4e-10</ixz>
            <iyy>3.05318e-06</iyy>
            <iyz>0</iyz>
            <izz>3.04657e-06</izz>
          </inertia>
        </inertial>
        <collision name='l_finger_2_link_median_bar_underactuated_collision'>
          <pose>0.01905 0 0 0 -0 0</pose>
          <geometry>
            <box>
              <size>0.0381 0.0075 0.002</size>
            </box>
          </geometry>
          <surface>
            <contact>
              <ode/>
            </contact>
            <friction>
              <ode>
                <mu>1.1</mu>
                <mu2>1.1</mu2>
              </ode>
            </friction>
            <bounce/>
          </surface>
          <max_contacts>10</max_contacts>
        </collision>
        <visual name='l_finger_2_link_median_bar_underactuated_visual'>
          <pose>0.01905 0 0 0 -0 0</pose>
          <geometry>
            <box>
              <size>0.0381 0.0075 0.002</size>
            </box>
          </geometry>
        </visual>
        <gravity>1</gravity>
        <velocity_decay/>
        <self_collide>0</self_collide>
        <kinematic>0</kinematic>
      </link>
      <joint name='l_finger_2_joint_paramedian_hinge_median_bar_underactuated' type='revolute'>
        <child>l_finger_2_link_median_bar_underactuated</child>
        <parent>l_finger_2_link_paramedian_hinge</parent>
        <axis>
          <xyz>7e-06 0 -1</xyz>
          <limit>
            <lower>-3.1416</lower>
            <upper>3.1416</upper>
            <effort>100</effort>
            <velocity>100</velocity>
          </limit>
          <dynamics>
            <spring_reference>0</spring_reference>
            <spring_stiffness>0</spring_stiffness>
          </dynamics>
          <use_parent_model_frame>1</use_parent_model_frame>
        </axis>
        <physics>
          <ode>
            <implicit_spring_damper>1</implicit_spring_damper>
            <cfm_damping>1</cfm_damping>
            <limit>
              <cfm>0</cfm>
              <erp>0.2</erp>
            </limit>
          </ode>
        </physics>
      </joint>
      <link name='l_finger_2_link_paraproximal_actuating_hinge'>
        <pose>0.331364 0.045517 -0.026 3.14159 3.64903e-06 2.0922</pose>
        <inertial>
          <pose>0.0064 0 0 0 -0 0</pose>
          <mass>0.00362</mass>
          <inertia>
            <ixx>1.2043e-07</ixx>
            <ixy>0</ixy>
            <ixz>0</ixz>
            <iyy>5.3588e-07</iyy>
            <iyz>0</iyz>
            <izz>6.5322e-07</izz>
          </inertia>
        </inertial>
        <collision name='l_finger_2_link_paraproximal_actuating_hinge_collision'>
          <pose>0.01143 0 0 0 -0 0</pose>
          <geometry>
            <box>
              <size>0.02286 0.0075 0.002</size>
            </box>
          </geometry>
          <surface>
            <contact>
              <ode/>
            </contact>
            <friction>
              <ode>
                <mu>1.1</mu>
                <mu2>1.1</mu2>
              </ode>
            </friction>
            <bounce/>
          </surface>
          <max_contacts>10</max_contacts>
        </collision>
        <visual name='l_finger_2_link_paraproximal_actuating_hinge_visual'>
          <pose>0.01143 0 0 0 -0 0</pose>
          <geometry>
            <box>
              <size>0.02286 0.0075 0.002</size>
            </box>
          </geometry>
        </visual>
        <gravity>1</gravity>
        <velocity_decay/>
        <self_collide>0</self_collide>
        <kinematic>0</kinematic>
      </link>
      <joint name='l_finger_2_joint_paraproximal_actuating_hinge' type='revolute'>
        <child>l_finger_2_link_paraproximal_actuating_hinge</child>
        <parent>l_finger_2_link_0</parent>
        <axis>
          <xyz>7e-06 0 -1</xyz>
          <limit>
            <lower>-3.1416</lower>
            <upper>3.1416</upper>
            <effort>100</effort>
            <velocity>100</velocity>
          </limit>
          <dynamics>
            <spring_reference>0</spring_reference>
            <spring_stiffness>0</spring_stiffness>
          </dynamics>
          <use_parent_model_frame>1</use_parent_model_frame>
        </axis>
        <physics>
          <ode>
            <implicit_spring_damper>1</implicit_spring_damper>
            <cfm_damping>1</cfm_damping>
            <limit>
              <cfm>0</cfm>
              <erp>0.2</erp>
            </limit>
          </ode>
        </physics>
      </joint>
      <link name='l_finger_2_link_paraproximal_bar'>
        <pose>0.319977 0.0653395 -0.0260001 3.14159 -6.37316e-06 0.52219</pose>
        <inertial>
          <pose>0.02858 -0.00129 0 0 -0 0</pose>
          <mass>0.00732</mass>
          <inertia>
            <ixx>9.065e-08</ixx>
            <ixy>-2.7047e-07</ixy>
            <ixz>1.42e-09</ixz>
            <iyy>8.78034e-06</iyy>
            <iyz>0</iyz>
            <izz>8.77558e-06</izz>
          </inertia>
        </inertial>
        <collision name='l_finger_2_link_paraproximal_bar_collision'>
          <pose>0.02885 0 0 0 -0 0</pose>
          <geometry>
            <box>
              <size>0.0577 0.0075 0.002</size>
            </box>
          </geometry>
          <surface>
            <contact>
              <ode/>
            </contact>
            <friction>
              <ode>
                <mu>1.1</mu>
                <mu2>1.1</mu2>
              </ode>
            </friction>
            <bounce/>
          </surface>
          <max_contacts>10</max_contacts>
        </collision>
        <visual name='l_finger_2_link_paraproximal_bar_visual'>
          <pose>0.02885 0 0 0 -0 0</pose>
          <geometry>
            <box>
              <size>0.0577 0.0075 0.002</size>
            </box>
          </geometry>
        </visual>
        <gravity>1</gravity>
        <velocity_decay/>
        <self_collide>0</self_collide>
        <kinematic>0</kinematic>
      </link>
      <joint name='l_finger_2_joint_paraproximal_bar' type='revolute'>
        <child>l_finger_2_link_paraproximal_bar</child>
        <parent>l_finger_2_link_paraproximal_actuating_hinge</parent>
        <axis>
          <xyz>7e-06 0 -1</xyz>
          <limit>
            <lower>-3.1416</lower>
            <upper>3.1416</upper>
            <effort>100</effort>
            <velocity>100</velocity>
          </limit>
          <dynamics>
            <spring_reference>0</spring_reference>
            <spring_stiffness>0</spring_stiffness>
          </dynamics>
          <use_parent_model_frame>1</use_parent_model_frame>
        </axis>
        <physics>
          <ode>
            <implicit_spring_damper>1</implicit_spring_damper>
            <cfm_damping>1</cfm_damping>
            <limit>
              <cfm>0</cfm>
              <erp>0.2</erp>
            </limit>
          </ode>
        </physics>
      </joint>
      <link name='l_finger_2_link_proximal_actuating_hinge'>
        <pose>0.331364 0.045517 -0.046 3.14159 3.64903e-06 2.0922</pose>
        <inertial>
          <pose>0.0012 -0.00162 -0.00161 0 -0 0</pose>
          <mass>0.02647</mass>
          <inertia>
            <ixx>1.56447e-06</ixx>
            <ixy>2.36226e-07</ixy>
            <ixz>-1.4862e-07</ixz>
            <iyy>2.21068e-06</iyy>
            <iyz>-1.4369e-07</iyz>
            <izz>3.23175e-06</izz>
          </inertia>
        </inertial>
        <collision name='l_finger_2_link_proximal_actuating_hinge_collision'>
          <pose>0.01429 0 0 0 -0 0</pose>
          <geometry>
            <box>
              <size>0.02858 0.0075 0.002</size>
            </box>
          </geometry>
          <surface>
            <contact>
              <ode/>
            </contact>
            <friction>
              <ode>
                <mu>1.1</mu>
                <mu2>1.1</mu2>
              </ode>
            </friction>
            <bounce/>
          </surface>
          <max_contacts>10</max_contacts>
        </collision>
        <visual name='l_finger_2_link_proximal_actuating_hinge_visual'>
          <pose>0.01429 0 0 0 -0 0</pose>
          <geometry>
            <box>
              <size>0.02858 0.0075 0.002</size>
            </box>
          </geometry>
        </visual>
        <gravity>1</gravity>
        <velocity_decay/>
        <self_collide>0</self_collide>
        <kinematic>0</kinematic>
      </link>
      <joint name='l_finger_2_joint_proximal_actuating_hinge' type='revolute'>
        <child>l_finger_2_link_proximal_actuating_hinge</child>
        <parent>l_finger_2_link_0</parent>
        <axis>
          <xyz>7e-06 0 -1</xyz>
          <limit>
            <lower>-3.1416</lower>
            <upper>3.1416</upper>
            <effort>100</effort>
            <velocity>100</velocity>
          </limit>
          <dynamics>
            <spring_reference>0</spring_reference>
            <spring_stiffness>0</spring_stiffness>
          </dynamics>
          <use_parent_model_frame>1</use_parent_model_frame>
        </axis>
        <physics>
          <ode>
            <implicit_spring_damper>1</implicit_spring_damper>
            <cfm_damping>1</cfm_damping>
            <limit>
              <cfm>0</cfm>
              <erp>0.2</erp>
            </limit>
          </ode>
        </physics>
      </joint>
      <link name='l_finger_2_link_proximal_actuating_bar'>
        <pose>0.317128 0.0702994 -0.0460001 3.14159 -7.15462e-06 0.23059</pose>
        <inertial>
          <pose>0.02699 -0.00122 0 0 -0 0</pose>
          <mass>0.00659</mass>
          <inertia>
            <ixx>8.348e-08</ixx>
            <ixy>-2.179e-07</ixy>
            <ixz>1.34e-09</ixz>
            <iyy>7.19076e-06</iyy>
            <iyz>0</iyz>
            <izz>7.18272e-06</izz>
          </inertia>
        </inertial>
        <collision name='l_finger_2_link_proximal_actuating_bar_collision'>
          <pose>0.026789 0 0 0 -0 0</pose>
          <geometry>
            <box>
              <size>0.05398 0.0075 0.002</size>
            </box>
          </geometry>
          <surface>
            <contact>
              <ode/>
            </contact>
            <friction>
              <ode>
                <mu>1.1</mu>
                <mu2>1.1</mu2>
              </ode>
            </friction>
            <bounce/>
          </surface>
          <max_contacts>10</max_contacts>
        </collision>
        <visual name='l_finger_2_link_proximal_actuating_bar_visual'>
          <pose>0.026789 0 0 0 -0 0</pose>
          <geometry>
            <box>
              <size>0.05398 0.0075 0.002</size>
            </box>
          </geometry>
        </visual>
        <gravity>1</gravity>
        <velocity_decay/>
        <self_collide>0</self_collide>
        <kinematic>0</kinematic>
      </link>
      <joint name='l_finger_2_joint_proximal_actuating_bar' type='revolute'>
        <child>l_finger_2_link_proximal_actuating_bar</child>
        <parent>l_finger_2_link_proximal_actuating_hinge</parent>
        <axis>
          <xyz>7e-06 0 -1</xyz>
          <limit>
            <lower>-3.1416</lower>
            <upper>3.1416</upper>
            <effort>100</effort>
            <velocity>100</velocity>
          </limit>
          <dynamics>
            <spring_reference>0</spring_reference>
            <spring_stiffness>0</spring_stiffness>
          </dynamics>
          <use_parent_model_frame>1</use_parent_model_frame>
        </axis>
        <physics>
          <ode>
            <implicit_spring_damper>1</implicit_spring_damper>
            <cfm_damping>1</cfm_damping>
            <limit>
              <cfm>0</cfm>
              <erp>0.2</erp>
            </limit>
          </ode>
        </physics>
      </joint>
      <link name='l_finger_middle_link_0'>
        <pose>0.331436 -0.0454829 0 0 -0 0</pose>
        <inertial>
          <pose>-0.01 0 0 0 -0 0</pose>
          <mass>0.1</mass>
          <inertia>
            <ixx>1.8e-05</ixx>
            <ixy>0</ixy>
            <ixz>0</ixz>
            <iyy>2.5e-05</iyy>
            <iyz>0</iyz>
            <izz>2.5e-05</izz>
          </inertia>
        </inertial>
        <collision name='l_finger_middle_link_0_collision'>
          <pose>0 0 0 0 -0 0</pose>
          <geometry>
            <mesh>
              <scale>1 1 1</scale>
              <uri>model://robotiq/meshes/s-model_articulated/collision/link_0.STL</uri>
            </mesh>
          </geometry>
          <surface>
            <contact>
              <ode/>
            </contact>
            <friction>
              <ode>
                <mu>1.1</mu>
                <mu2>1.1</mu2>
              </ode>
            </friction>
            <bounce/>
          </surface>
          <max_contacts>10</max_contacts>
        </collision>
        <visual name='l_finger_middle_link_0_visual'>
          <pose>0 0 0 0 -0 0</pose>
          <geometry>
            <mesh>
              <scale>1 1 1</scale>
              <uri>model://robotiq/meshes/s-model_articulated/visual/link_0.STL</uri>
            </mesh>
          </geometry>
        </visual>
        <gravity>1</gravity>
        <velocity_decay/>
        <self_collide>0</self_collide>
        <kinematic>0</kinematic>
      </link>
      <joint name='l_palm_finger_middle_joint' type='revolute'>
        <child>l_finger_middle_link_0</child>
        <parent>base_link</parent>
        <axis>
          <xyz>0 1 0</xyz>
          <limit>
            <lower>0</lower>
            <upper>0</upper>
            <effort>60</effort>
            <velocity>-1</velocity>
          </limit>
          <dynamics>
            <damping>1</damping>
            <friction>0</friction>
            <spring_reference>0</spring_reference>
            <spring_stiffness>0</spring_stiffness>
          </dynamics>
          <use_parent_model_frame>1</use_parent_model_frame>
        </axis>
        <physics>
          <ode>
            <implicit_spring_damper>1</implicit_spring_damper>
            <cfm_damping>1</cfm_damping>
            <limit>
              <cfm>0</cfm>
              <erp>0.2</erp>
            </limit>
          </ode>
        </physics>
      </joint>
      <link name='l_finger_middle_link_1'>
        <pose>0.331436 -0.0454829 0 0 0 -2.0906</pose>
        <inertial>
          <pose>0.00053 0.03218 0 0 -0 1.5708</pose>
          <mass>0.047</mass>
          <inertia>
            <ixx>4.99332e-06</ixx>
            <ixy>9.1312e-07</ixy>
            <ixz>-1.2e-09</ixz>
            <iyy>6.43453e-05</iyy>
            <iyz>-7e-11</iyz>
            <izz>6.06192e-05</izz>
          </inertia>
        </inertial>
        <collision name='l_finger_middle_link_1_collision'>
          <pose>0 0.05717 0 0 -0 1.5708</pose>
          <geometry>
            <mesh>
              <scale>1 1 1</scale>
              <uri>model://robotiq/meshes/s-model_articulated/collision/link_1.STL</uri>
            </mesh>
          </geometry>
          <surface>
            <contact>
              <ode/>
            </contact>
            <friction>
              <ode>
                <mu>1.1</mu>
                <mu2>1.1</mu2>
              </ode>
            </friction>
            <bounce/>
          </surface>
          <max_contacts>10</max_contacts>
        </collision>
        <visual name='l_finger_middle_link_1_visual'>
          <pose>0 0.05717 0 0 -0 1.5708</pose>
          <geometry>
            <mesh>
              <scale>1 1 1</scale>
              <uri>model://robotiq/meshes/s-model_articulated/visual/link_1.STL</uri>
            </mesh>
          </geometry>
        </visual>
        <gravity>1</gravity>
        <velocity_decay/>
        <self_collide>0</self_collide>
        <kinematic>0</kinematic>
      </link>
      <joint name='l_finger_middle_joint_1' type='revolute'>
        <child>l_finger_middle_link_1</child>
        <parent>l_finger_middle_link_0</parent>
        <axis>
          <xyz>0 0 1</xyz>
          <limit>
            <lower>0</lower>
            <upper>1.2217</upper>
            <effort>60</effort>
            <velocity>-1</velocity>
          </limit>
          <dynamics>
            <damping>1</damping>
            <friction>0</friction>
            <spring_reference>0</spring_reference>
            <spring_stiffness>0</spring_stiffness>
          </dynamics>
          <use_parent_model_frame>1</use_parent_model_frame>
        </axis>
        <physics>
          <ode>
            <implicit_spring_damper>1</implicit_spring_damper>
            <cfm_damping>1</cfm_damping>
            <limit>
              <cfm>0</cfm>
              <erp>0.2</erp>
            </limit>
          </ode>
        </physics>
      </joint>
      <link name='l_finger_middle_link_2'>
        <pose>0.381038 -0.07387 0 0 0 -2.0906</pose>
        <inertial>
          <pose>0.00048 0.02167 0.00018 0 -0 1.5708</pose>
          <mass>0.03284</mass>
          <inertia>
            <ixx>3.48008e-06</ixx>
            <ixy>3.194e-07</ixy>
            <ixz>1.3041e-07</ixz>
            <iyy>2.24812e-05</iyy>
            <iyz>2.91e-09</iyz>
            <izz>1.98635e-05</izz>
          </inertia>
        </inertial>
        <collision name='l_finger_middle_link_2_collision'>
          <pose>0 0.0381 0.0075 0 -0 1.5708</pose>
          <geometry>
            <mesh>
              <scale>1 1 1</scale>
              <uri>model://robotiq/meshes/s-model_articulated/collision/link_2.STL</uri>
            </mesh>
          </geometry>
          <surface>
            <contact>
              <ode/>
            </contact>
            <friction>
              <ode>
                <mu>1.1</mu>
                <mu2>1.1</mu2>
              </ode>
            </friction>
            <bounce/>
          </surface>
          <max_contacts>10</max_contacts>
        </collision>
        <visual name='l_finger_middle_link_2_visual'>
          <pose>0 0.0381 0.0075 0 -0 1.5708</pose>
          <geometry>
            <mesh>
              <scale>1 1 1</scale>
              <uri>model://robotiq/meshes/s-model_articulated/visual/link_2.STL</uri>
            </mesh>
          </geometry>
        </visual>
        <gravity>1</gravity>
        <velocity_decay/>
        <self_collide>0</self_collide>
        <kinematic>0</kinematic>
      </link>
      <joint name='l_finger_middle_joint_2' type='revolute'>
        <child>l_finger_middle_link_2</child>
        <parent>l_finger_middle_link_1</parent>
        <axis>
          <xyz>0 0 1</xyz>
          <limit>
            <lower>0</lower>
            <upper>1.5708</upper>
            <effort>60</effort>
            <velocity>-1</velocity>
          </limit>
          <dynamics>
            <damping>1</damping>
            <friction>0</friction>
            <spring_reference>0</spring_reference>
            <spring_stiffness>0</spring_stiffness>
          </dynamics>
          <use_parent_model_frame>1</use_parent_model_frame>
        </axis>
        <physics>
          <ode>
            <implicit_spring_damper>1</implicit_spring_damper>
            <cfm_damping>1</cfm_damping>
            <limit>
              <cfm>0</cfm>
              <erp>0.2</erp>
            </limit>
          </ode>
        </physics>
      </joint>
      <link name='l_finger_middle_link_3'>
        <pose>0.414886 -0.0932416 0 0 -0 0</pose>
        <inertial>
          <pose>0.01626 0.00049 0.0002 0 -0 0</pose>
          <mass>0.03354</mass>
          <inertia>
            <ixx>3.05151e-06</ixx>
            <ixy>8.9792e-07</ixy>
            <ixz>2.49e-09</ixz>
            <iyy>1.42798e-05</iyy>
            <iyz>-1.191e-08</iyz>
            <izz>1.26413e-05</izz>
          </inertia>
        </inertial>
        <collision name='l_finger_middle_link_3_collision'>
          <pose>0 0 0 0 -0 0</pose>
          <geometry>
            <mesh>
              <scale>1 1 1</scale>
              <uri>model://robotiq/meshes/s-model_articulated/collision/link_3.STL</uri>
            </mesh>
          </geometry>
          <surface>
            <contact>
              <ode/>
            </contact>
            <friction>
              <ode>
                <mu>1.1</mu>
                <mu2>1.1</mu2>
              </ode>
            </friction>
            <bounce/>
          </surface>
          <max_contacts>10</max_contacts>
        </collision>
        <visual name='l_finger_middle_link_3_visual'>
          <pose>0 0 0 0 -0 0</pose>
          <geometry>
            <mesh>
              <scale>1 1 1</scale>
              <uri>model://robotiq/meshes/s-model_articulated/visual/link_3.STL</uri>
            </mesh>
          </geometry>
        </visual>
        <gravity>1</gravity>
        <velocity_decay/>
        <self_collide>0</self_collide>
        <kinematic>0</kinematic>
      </link>
      <joint name='l_finger_middle_joint_3' type='revolute'>
        <child>l_finger_middle_link_3</child>
        <parent>l_finger_middle_link_2</parent>
        <axis>
          <xyz>0 0 1</xyz>
          <limit>
            <lower>-0.6632</lower>
            <upper>1.0471</upper>
            <effort>60</effort>
            <velocity>-1</velocity>
          </limit>
          <dynamics>
            <damping>1</damping>
            <friction>0</friction>
            <spring_reference>0</spring_reference>
            <spring_stiffness>0</spring_stiffness>
          </dynamics>
          <use_parent_model_frame>1</use_parent_model_frame>
        </axis>
        <physics>
          <ode>
            <implicit_spring_damper>1</implicit_spring_damper>
            <cfm_damping>1</cfm_damping>
            <limit>
              <cfm>0</cfm>
              <erp>0.2</erp>
            </limit>
          </ode>
        </physics>
      </joint>
      <link name='l_finger_middle_link_paradistal_hinge'>
        <pose>0.414886 -0.0932416 -0.01 0 0 -2.0906</pose>
        <inertial>
          <pose>0.00548 0 0 0 -0 0</pose>
          <mass>0.00158</mass>
          <inertia>
            <ixx>1.907e-08</ixx>
            <ixy>0</ixy>
            <ixz>0</ixz>
            <iyy>1.097e-07</iyy>
            <iyz>0</iyz>
            <izz>1.261e-07</izz>
          </inertia>
        </inertial>
        <collision name='l_finger_middle_link_paradistal_hinge_collision'>
          <pose>0 0 0 0 -0 0</pose>
          <geometry>
            <box>
              <size>0.02 0.02 0.002</size>
            </box>
          </geometry>
          <surface>
            <contact>
              <ode/>
            </contact>
            <friction>
              <ode>
                <mu>1.1</mu>
                <mu2>1.1</mu2>
              </ode>
            </friction>
            <bounce/>
          </surface>
          <max_contacts>10</max_contacts>
        </collision>
        <visual name='l_finger_middle_link_paradistal_hinge_visual'>
          <pose>0 0 0 0 -0 0</pose>
          <geometry>
            <box>
              <size>0.02 0.02 0.002</size>
            </box>
          </geometry>
        </visual>
        <gravity>1</gravity>
        <velocity_decay/>
        <self_collide>0</self_collide>
        <kinematic>0</kinematic>
      </link>
      <joint name='l_finger_middle_joint_paradistal_hinge' type='revolute'>
        <child>l_finger_middle_link_paradistal_hinge</child>
        <parent>l_finger_middle_link_2</parent>
        <axis>
          <xyz>0 0 1</xyz>
          <limit>
            <lower>-3.1416</lower>
            <upper>3.1416</upper>
            <effort>100</effort>
            <velocity>100</velocity>
          </limit>
          <dynamics>
            <spring_reference>0</spring_reference>
            <spring_stiffness>0</spring_stiffness>
          </dynamics>
          <use_parent_model_frame>1</use_parent_model_frame>
        </axis>
        <physics>
          <ode>
            <implicit_spring_damper>1</implicit_spring_damper>
            <cfm_damping>1</cfm_damping>
            <limit>
              <cfm>0</cfm>
              <erp>0.2</erp>
            </limit>
          </ode>
        </physics>
      </joint>
      <link name='l_finger_middle_link_median_actuating_hinge'>
        <pose>0.381038 -0.07387 0.01 0 0 -2.4606</pose>
        <inertial>
          <pose>0.0092 0.00514 0 0 -0 0</pose>
          <mass>0.00359</mass>
          <inertia>
            <ixx>2.4735e-07</ixx>
            <ixy>2.3619e-07</ixy>
            <ixz>0</ixz>
            <iyy>4.7681e-07</iyy>
            <iyz>0</iyz>
            <izz>7.1813e-07</izz>
          </inertia>
        </inertial>
        <collision name='l_finger_middle_link_median_actuating_hinge_collision'>
          <pose>0 0 0 0 -0 0</pose>
          <geometry>
            <box>
              <size>0.02 0.02 0.002</size>
            </box>
          </geometry>
          <surface>
            <contact>
              <ode/>
            </contact>
            <friction>
              <ode>
                <mu>1.1</mu>
                <mu2>1.1</mu2>
              </ode>
            </friction>
            <bounce/>
          </surface>
          <max_contacts>10</max_contacts>
        </collision>
        <visual name='l_finger_middle_link_median_actuating_hinge_visual'>
          <pose>0 0 0 0 -0 0</pose>
          <geometry>
            <box>
              <size>0.02 0.02 0.002</size>
            </box>
          </geometry>
        </visual>
        <gravity>1</gravity>
        <velocity_decay/>
        <self_collide>0</self_collide>
        <kinematic>0</kinematic>
      </link>
      <joint name='l_finger_middle_joint_median_actuating_hinge' type='revolute'>
        <child>l_finger_middle_link_median_actuating_hinge</child>
        <parent>l_finger_middle_link_1</parent>
        <axis>
          <xyz>0 0 1</xyz>
          <limit>
            <lower>-3.1416</lower>
            <upper>3.1416</upper>
            <effort>100</effort>
            <velocity>100</velocity>
          </limit>
          <dynamics>
            <spring_reference>0</spring_reference>
            <spring_stiffness>0</spring_stiffness>
          </dynamics>
          <use_parent_model_frame>1</use_parent_model_frame>
        </axis>
        <physics>
          <ode>
            <implicit_spring_damper>1</implicit_spring_damper>
            <cfm_damping>1</cfm_damping>
            <limit>
              <cfm>0</cfm>
              <erp>0.2</erp>
            </limit>
          </ode>
        </physics>
      </joint>
      <link name='l_finger_middle_link_median_bar'>
        <pose>0.377956 -0.0958789 0.01 0 0 -0.1391</pose>
        <inertial>
          <pose>0.01905 -0.00107 0 0 -0 0</pose>
          <mass>0.00538</mass>
          <inertia>
            <ixx>6.639e-08</ixx>
            <ixy>-1.0996e-07</ixy>
            <ixz>9.4e-10</ixz>
            <iyy>3.05318e-06</iyy>
            <iyz>0</iyz>
            <izz>3.04657e-06</izz>
          </inertia>
        </inertial>
        <collision name='l_finger_middle_link_median_bar_collision'>
          <pose>0.01905 0 0 0 -0 0</pose>
          <geometry>
            <box>
              <size>0.0381 0.0075 0.002</size>
            </box>
          </geometry>
          <surface>
            <contact>
              <ode/>
            </contact>
            <friction>
              <ode>
                <mu>1.1</mu>
                <mu2>1.1</mu2>
              </ode>
            </friction>
            <bounce/>
          </surface>
          <max_contacts>10</max_contacts>
        </collision>
        <visual name='l_finger_middle_link_median_bar_visual'>
          <pose>0.01905 0 0 0 -0 0</pose>
          <geometry>
            <box>
              <size>0.0381 0.0075 0.002</size>
            </box>
          </geometry>
        </visual>
        <gravity>1</gravity>
        <velocity_decay/>
        <self_collide>0</self_collide>
        <kinematic>0</kinematic>
      </link>
      <joint name='l_finger_middle_joint_median_actuating_hinge_median_bar' type='revolute'>
        <child>l_finger_middle_link_median_bar</child>
        <parent>l_finger_middle_link_median_actuating_hinge</parent>
        <axis>
          <xyz>0 0 1</xyz>
          <limit>
            <lower>-3.1416</lower>
            <upper>3.1416</upper>
            <effort>100</effort>
            <velocity>100</velocity>
          </limit>
          <dynamics>
            <spring_reference>0</spring_reference>
            <spring_stiffness>0</spring_stiffness>
          </dynamics>
          <use_parent_model_frame>1</use_parent_model_frame>
        </axis>
        <physics>
          <ode>
            <implicit_spring_damper>1</implicit_spring_damper>
            <cfm_damping>1</cfm_damping>
            <limit>
              <cfm>0</cfm>
              <erp>0.2</erp>
            </limit>
          </ode>
        </physics>
      </joint>
      <link name='l_finger_middle_link_paramedian_hinge'>
        <pose>0.381038 -0.07387 -0.01 0 0 -2.0906</pose>
        <inertial>
          <pose>-0.01025 0.00046 0 0 -0 0</pose>
          <mass>0.00276</mass>
          <inertia>
            <ixx>4.213e-08</ixx>
            <ixy>-1.491e-08</ixy>
            <ixz>0</ixz>
            <iyy>5.0258e-07</iyy>
            <iyz>0</iyz>
            <izz>5.4007e-07</izz>
          </inertia>
        </inertial>
        <collision name='l_finger_middle_link_paramedian_hinge_collision'>
          <pose>0 0 0 0 -0 0</pose>
          <geometry>
            <box>
              <size>0.02 0.02 0.002</size>
            </box>
          </geometry>
          <surface>
            <contact>
              <ode/>
            </contact>
            <friction>
              <ode>
                <mu>1.1</mu>
                <mu2>1.1</mu2>
              </ode>
            </friction>
            <bounce/>
          </surface>
          <max_contacts>10</max_contacts>
        </collision>
        <visual name='l_finger_middle_link_paramedian_hinge_visual'>
          <pose>0 0 0 0 -0 0</pose>
          <geometry>
            <box>
              <size>0.02 0.02 0.002</size>
            </box>
          </geometry>
        </visual>
        <gravity>1</gravity>
        <velocity_decay/>
        <self_collide>0</self_collide>
        <kinematic>0</kinematic>
      </link>
      <joint name='l_finger_middle_joint_paramedian_hinge' type='revolute'>
        <child>l_finger_middle_link_paramedian_hinge</child>
        <parent>l_finger_middle_link_1</parent>
        <axis>
          <xyz>0 0 1</xyz>
          <limit>
            <lower>-3.1416</lower>
            <upper>3.1416</upper>
            <effort>100</effort>
            <velocity>100</velocity>
          </limit>
          <dynamics>
            <spring_reference>0</spring_reference>
            <spring_stiffness>0</spring_stiffness>
          </dynamics>
          <use_parent_model_frame>1</use_parent_model_frame>
        </axis>
        <physics>
          <ode>
            <implicit_spring_damper>1</implicit_spring_damper>
            <cfm_damping>1</cfm_damping>
            <limit>
              <cfm>0</cfm>
              <erp>0.2</erp>
            </limit>
          </ode>
        </physics>
      </joint>
      <link name='l_finger_middle_link_median_bar_underactuated'>
        <pose>0.377799 -0.0861534 -0.01 0 0 -0.5198</pose>
        <inertial>
          <pose>0.01905 -0.00107 0 0 -0 0</pose>
          <mass>0.00538</mass>
          <inertia>
            <ixx>6.639e-08</ixx>
            <ixy>-1.0996e-07</ixy>
            <ixz>-9.4e-10</ixz>
            <iyy>3.05318e-06</iyy>
            <iyz>0</iyz>
            <izz>3.04657e-06</izz>
          </inertia>
        </inertial>
        <collision name='l_finger_middle_link_median_bar_underactuated_collision'>
          <pose>0.01905 0 0 0 -0 0</pose>
          <geometry>
            <box>
              <size>0.0381 0.0075 0.002</size>
            </box>
          </geometry>
          <surface>
            <contact>
              <ode/>
            </contact>
            <friction>
              <ode>
                <mu>1.1</mu>
                <mu2>1.1</mu2>
              </ode>
            </friction>
            <bounce/>
          </surface>
          <max_contacts>10</max_contacts>
        </collision>
        <visual name='l_finger_middle_link_median_bar_underactuated_visual'>
          <pose>0.01905 0 0 0 -0 0</pose>
          <geometry>
            <box>
              <size>0.0381 0.0075 0.002</size>
            </box>
          </geometry>
        </visual>
        <gravity>1</gravity>
        <velocity_decay/>
        <self_collide>0</self_collide>
        <kinematic>0</kinematic>
      </link>
      <joint name='l_finger_middle_joint_paramedian_hinge_median_bar_underactuated' type='revolute'>
        <child>l_finger_middle_link_median_bar_underactuated</child>
        <parent>l_finger_middle_link_paramedian_hinge</parent>
        <axis>
          <xyz>0 0 1</xyz>
          <limit>
            <lower>-3.1416</lower>
            <upper>3.1416</upper>
            <effort>100</effort>
            <velocity>100</velocity>
          </limit>
          <dynamics>
            <spring_reference>0</spring_reference>
            <spring_stiffness>0</spring_stiffness>
          </dynamics>
          <use_parent_model_frame>1</use_parent_model_frame>
        </axis>
        <physics>
          <ode>
            <implicit_spring_damper>1</implicit_spring_damper>
            <cfm_damping>1</cfm_damping>
            <limit>
              <cfm>0</cfm>
              <erp>0.2</erp>
            </limit>
          </ode>
        </physics>
      </joint>
      <link name='l_finger_middle_link_paraproximal_actuating_hinge'>
        <pose>0.331436 -0.0454829 -0.01 0 0 -2.0906</pose>
        <inertial>
          <pose>0.0064 0 0 0 -0 0</pose>
          <mass>0.00362</mass>
          <inertia>
            <ixx>1.2043e-07</ixx>
            <ixy>0</ixy>
            <ixz>0</ixz>
            <iyy>5.3588e-07</iyy>
            <iyz>0</iyz>
            <izz>6.5322e-07</izz>
          </inertia>
        </inertial>
        <collision name='l_finger_middle_link_paraproximal_actuating_hinge_collision'>
          <pose>0.01143 0 0 0 -0 0</pose>
          <geometry>
            <box>
              <size>0.02286 0.0075 0.002</size>
            </box>
          </geometry>
          <surface>
            <contact>
              <ode/>
            </contact>
            <friction>
              <ode>
                <mu>1.1</mu>
                <mu2>1.1</mu2>
              </ode>
            </friction>
            <bounce/>
          </surface>
          <max_contacts>10</max_contacts>
        </collision>
        <visual name='l_finger_middle_link_paraproximal_actuating_hinge_visual'>
          <pose>0.01143 0 0 0 -0 0</pose>
          <geometry>
            <box>
              <size>0.02286 0.0075 0.002</size>
            </box>
          </geometry>
        </visual>
        <gravity>1</gravity>
        <velocity_decay/>
        <self_collide>0</self_collide>
        <kinematic>0</kinematic>
      </link>
      <joint name='l_finger_middle_joint_paraproximal_actuating_hinge' type='revolute'>
        <child>l_finger_middle_link_paraproximal_actuating_hinge</child>
        <parent>l_finger_middle_link_0</parent>
        <axis>
          <xyz>0 0 1</xyz>
          <limit>
            <lower>-3.1416</lower>
            <upper>3.1416</upper>
            <effort>100</effort>
            <velocity>100</velocity>
          </limit>
          <dynamics>
            <spring_reference>0</spring_reference>
            <spring_stiffness>0</spring_stiffness>
          </dynamics>
          <use_parent_model_frame>1</use_parent_model_frame>
        </axis>
        <physics>
          <ode>
            <implicit_spring_damper>1</implicit_spring_damper>
            <cfm_damping>1</cfm_damping>
            <limit>
              <cfm>0</cfm>
              <erp>0.2</erp>
            </limit>
          </ode>
        </physics>
      </joint>
      <link name='l_finger_middle_link_paraproximal_bar'>
        <pose>0.320081 -0.0653235 -0.01 0 0 -0.5206</pose>
        <inertial>
          <pose>0.02858 -0.00129 0 0 -0 0</pose>
          <mass>0.00732</mass>
          <inertia>
            <ixx>9.065e-08</ixx>
            <ixy>-2.7047e-07</ixy>
            <ixz>1.42e-09</ixz>
            <iyy>8.78034e-06</iyy>
            <iyz>0</iyz>
            <izz>8.77558e-06</izz>
          </inertia>
        </inertial>
        <collision name='l_finger_middle_link_paraproximal_bar_collision'>
          <pose>0.02885 0 0 0 -0 0</pose>
          <geometry>
            <box>
              <size>0.0577 0.0075 0.002</size>
            </box>
          </geometry>
          <surface>
            <contact>
              <ode/>
            </contact>
            <friction>
              <ode>
                <mu>1.1</mu>
                <mu2>1.1</mu2>
              </ode>
            </friction>
            <bounce/>
          </surface>
          <max_contacts>10</max_contacts>
        </collision>
        <visual name='l_finger_middle_link_paraproximal_bar_visual'>
          <pose>0.02885 0 0 0 -0 0</pose>
          <geometry>
            <box>
              <size>0.0577 0.0075 0.002</size>
            </box>
          </geometry>
        </visual>
        <gravity>1</gravity>
        <velocity_decay/>
        <self_collide>0</self_collide>
        <kinematic>0</kinematic>
      </link>
      <joint name='l_finger_middle_joint_paraproximal_bar' type='revolute'>
        <child>l_finger_middle_link_paraproximal_bar</child>
        <parent>l_finger_middle_link_paraproximal_actuating_hinge</parent>
        <axis>
          <xyz>0 0 1</xyz>
          <limit>
            <lower>-3.1416</lower>
            <upper>3.1416</upper>
            <effort>100</effort>
            <velocity>100</velocity>
          </limit>
          <dynamics>
            <spring_reference>0</spring_reference>
            <spring_stiffness>0</spring_stiffness>
          </dynamics>
          <use_parent_model_frame>1</use_parent_model_frame>
        </axis>
        <physics>
          <ode>
            <implicit_spring_damper>1</implicit_spring_damper>
            <cfm_damping>1</cfm_damping>
            <limit>
              <cfm>0</cfm>
              <erp>0.2</erp>
            </limit>
          </ode>
        </physics>
      </joint>
      <link name='l_finger_middle_link_proximal_actuating_hinge'>
        <pose>0.331436 -0.0454829 0.01 0 0 -2.0906</pose>
        <inertial>
          <pose>0.0012 -0.00162 -0.00161 0 -0 0</pose>
          <mass>0.02647</mass>
          <inertia>
            <ixx>1.56447e-06</ixx>
            <ixy>2.36226e-07</ixy>
            <ixz>-1.4862e-07</ixz>
            <iyy>2.21068e-06</iyy>
            <iyz>-1.4369e-07</iyz>
            <izz>3.23175e-06</izz>
          </inertia>
        </inertial>
        <collision name='l_finger_middle_link_proximal_actuating_hinge_collision'>
          <pose>0.01429 0 0 0 -0 0</pose>
          <geometry>
            <box>
              <size>0.02858 0.0075 0.002</size>
            </box>
          </geometry>
          <surface>
            <contact>
              <ode/>
            </contact>
            <friction>
              <ode>
                <mu>1.1</mu>
                <mu2>1.1</mu2>
              </ode>
            </friction>
            <bounce/>
          </surface>
          <max_contacts>10</max_contacts>
        </collision>
        <visual name='l_finger_middle_link_proximal_actuating_hinge_visual'>
          <pose>0.01429 0 0 0 -0 0</pose>
          <geometry>
            <box>
              <size>0.02858 0.0075 0.002</size>
            </box>
          </geometry>
        </visual>
        <gravity>1</gravity>
        <velocity_decay/>
        <self_collide>0</self_collide>
        <kinematic>0</kinematic>
      </link>
      <joint name='l_finger_middle_joint_proximal_actuating_hinge' type='revolute'>
        <child>l_finger_middle_link_proximal_actuating_hinge</child>
        <parent>l_finger_middle_link_0</parent>
        <axis>
          <xyz>0 0 1</xyz>
          <limit>
            <lower>-3.1416</lower>
            <upper>3.1416</upper>
            <effort>100</effort>
            <velocity>100</velocity>
          </limit>
          <dynamics>
            <spring_reference>0</spring_reference>
            <spring_stiffness>0</spring_stiffness>
          </dynamics>
          <use_parent_model_frame>1</use_parent_model_frame>
        </axis>
        <physics>
          <ode>
            <implicit_spring_damper>1</implicit_spring_damper>
            <cfm_damping>1</cfm_damping>
            <limit>
              <cfm>0</cfm>
              <erp>0.2</erp>
            </limit>
          </ode>
        </physics>
      </joint>
      <link name='l_finger_middle_link_proximal_actuating_bar'>
        <pose>0.31724 -0.070288 0.01 0 0 -0.229</pose>
        <inertial>
          <pose>0.02699 -0.00122 0 0 -0 0</pose>
          <mass>0.00659</mass>
          <inertia>
            <ixx>8.348e-08</ixx>
            <ixy>-2.179e-07</ixy>
            <ixz>1.34e-09</ixz>
            <iyy>7.19076e-06</iyy>
            <iyz>0</iyz>
            <izz>7.18272e-06</izz>
          </inertia>
        </inertial>
        <collision name='l_finger_middle_link_proximal_actuating_bar_collision'>
          <pose>0.026789 0 0 0 -0 0</pose>
          <geometry>
            <box>
              <size>0.05398 0.0075 0.002</size>
            </box>
          </geometry>
          <surface>
            <contact>
              <ode/>
            </contact>
            <friction>
              <ode>
                <mu>1.1</mu>
                <mu2>1.1</mu2>
              </ode>
            </friction>
            <bounce/>
          </surface>
          <max_contacts>10</max_contacts>
        </collision>
        <visual name='l_finger_middle_link_proximal_actuating_bar_visual'>
          <pose>0.026789 0 0 0 -0 0</pose>
          <geometry>
            <box>
              <size>0.05398 0.0075 0.002</size>
            </box>
          </geometry>
        </visual>
        <gravity>1</gravity>
        <velocity_decay/>
        <self_collide>0</self_collide>
        <kinematic>0</kinematic>
      </link>
      <joint name='l_finger_middle_joint_proximal_actuating_bar' type='revolute'>
        <child>l_finger_middle_link_proximal_actuating_bar</child>
        <parent>l_finger_middle_link_proximal_actuating_hinge</parent>
        <axis>
          <xyz>0 0 1</xyz>
          <limit>
            <lower>-3.1416</lower>
            <upper>3.1416</upper>
            <effort>100</effort>
            <velocity>100</velocity>
          </limit>
          <dynamics>
            <spring_reference>0</spring_reference>
            <spring_stiffness>0</spring_stiffness>
          </dynamics>
          <use_parent_model_frame>1</use_parent_model_frame>
        </axis>
        <physics>
          <ode>
            <implicit_spring_damper>1</implicit_spring_damper>
            <cfm_damping>1</cfm_damping>
            <limit>
              <cfm>0</cfm>
              <erp>0.2</erp>
            </limit>
          </ode>
        </physics>
      </joint>
      <joint name='l_finger_1_link_proximal_actuating_bar_median_actuating_hinge_couple' type='revolute'>
        <parent>l_finger_1_link_median_actuating_hinge</parent>
        <child>l_finger_1_link_proximal_actuating_bar</child>
        <pose>0.05398 0 0 0 -0 0</pose>
        <axis>
          <dynamics>
            <damping>0</damping>
            <friction>0</friction>
            <spring_reference>0</spring_reference>
            <spring_stiffness>0</spring_stiffness>
          </dynamics>
          <xyz>0 0 1</xyz>
          <use_parent_model_frame>1</use_parent_model_frame>
          <limit>
            <lower>-1e+16</lower>
            <upper>1e+16</upper>
          </limit>
        </axis>
      </joint>
      <joint name='l_finger_1_link_median_bar_link_3_couple' type='revolute'>
        <parent>l_finger_1_link_3</parent>
        <child>l_finger_1_link_median_bar</child>
        <pose>0.0381 0 0 0 -0 0</pose>
        <axis>
          <dynamics>
            <damping>0</damping>
            <friction>0</friction>
            <spring_reference>0</spring_reference>
            <spring_stiffness>0</spring_stiffness>
          </dynamics>
          <xyz>0 0 1</xyz>
          <use_parent_model_frame>1</use_parent_model_frame>
          <limit>
            <lower>-1e+16</lower>
            <upper>1e+16</upper>
          </limit>
        </axis>
      </joint>
      <joint name='l_finger_1_link_paramedian_bar_paradistal_hinge_couple' type='revolute'>
        <parent>l_finger_1_link_paradistal_hinge</parent>
        <child>l_finger_1_link_median_bar_underactuated</child>
        <pose>0.0381 0 0 0 -0 0</pose>
        <axis>
          <dynamics>
            <damping>0</damping>
            <friction>0</friction>
            <spring_reference>0</spring_reference>
            <spring_stiffness>0</spring_stiffness>
          </dynamics>
          <xyz>0 0 1</xyz>
          <use_parent_model_frame>1</use_parent_model_frame>
          <limit>
            <lower>-1e+16</lower>
            <upper>1e+16</upper>
          </limit>
        </axis>
      </joint>
      <joint name='l_finger_1_link_paradistal_hinge_link_3_couple' type='revolute'>
        <parent>l_finger_1_link_paradistal_hinge</parent>
        <child>l_finger_1_link_3</child>
        <pose>0.0381 0 0 0 -0 0</pose>
        <axis>
          <dynamics>
            <damping>0</damping>
            <friction>0</friction>
            <spring_reference>0</spring_reference>
            <spring_stiffness>0</spring_stiffness>
          </dynamics>
          <xyz>0 0 1</xyz>
          <use_parent_model_frame>1</use_parent_model_frame>
          <limit>
            <lower>-1e+16</lower>
            <upper>1e+16</upper>
          </limit>
        </axis>
      </joint>
      <joint name='l_finger_1_link_paraproximal_bar_paramedian_hinge_couple' type='revolute'>
        <parent>l_finger_1_link_paramedian_hinge</parent>
        <child>l_finger_1_link_paraproximal_bar</child>
        <pose>0.0577 0 0 0 -0 0</pose>
        <axis>
          <dynamics>
            <damping>0</damping>
            <friction>0</friction>
            <spring_reference>0</spring_reference>
            <spring_stiffness>0</spring_stiffness>
          </dynamics>
          <xyz>0 0 1</xyz>
          <use_parent_model_frame>1</use_parent_model_frame>
          <limit>
            <lower>-1e+16</lower>
            <upper>1e+16</upper>
          </limit>
        </axis>
      </joint>
      <joint name='l_finger_2_link_proximal_actuating_bar_median_actuating_hinge_couple' type='revolute'>
        <parent>l_finger_2_link_median_actuating_hinge</parent>
        <child>l_finger_2_link_proximal_actuating_bar</child>
        <pose>0.05398 0 0 0 -0 0</pose>
        <axis>
          <dynamics>
            <damping>0</damping>
            <friction>0</friction>
            <spring_reference>0</spring_reference>
            <spring_stiffness>0</spring_stiffness>
          </dynamics>
          <xyz>0 0 1</xyz>
          <use_parent_model_frame>1</use_parent_model_frame>
          <limit>
            <lower>-1e+16</lower>
            <upper>1e+16</upper>
          </limit>
        </axis>
      </joint>
      <joint name='l_finger_2_link_median_bar_link_3_couple' type='revolute'>
        <parent>l_finger_2_link_3</parent>
        <child>l_finger_2_link_median_bar</child>
        <pose>0.0381 0 0 0 -0 0</pose>
        <axis>
          <dynamics>
            <damping>0</damping>
            <friction>0</friction>
            <spring_reference>0</spring_reference>
            <spring_stiffness>0</spring_stiffness>
          </dynamics>
          <xyz>0 0 1</xyz>
          <use_parent_model_frame>1</use_parent_model_frame>
          <limit>
            <lower>-1e+16</lower>
            <upper>1e+16</upper>
          </limit>
        </axis>
      </joint>
      <joint name='l_finger_2_link_paramedian_bar_paradistal_hinge_couple' type='revolute'>
        <parent>l_finger_2_link_paradistal_hinge</parent>
        <child>l_finger_2_link_median_bar_underactuated</child>
        <pose>0.0381 0 0 0 -0 0</pose>
        <axis>
          <dynamics>
            <damping>0</damping>
            <friction>0</friction>
            <spring_reference>0</spring_reference>
            <spring_stiffness>0</spring_stiffness>
          </dynamics>
          <xyz>0 0 1</xyz>
          <use_parent_model_frame>1</use_parent_model_frame>
          <limit>
            <lower>-1e+16</lower>
            <upper>1e+16</upper>
          </limit>
        </axis>
      </joint>
      <joint name='l_finger_2_link_paradistal_hinge_link_3_couple' type='revolute'>
        <parent>l_finger_2_link_paradistal_hinge</parent>
        <child>l_finger_2_link_3</child>
        <pose>0.0381 0 0 0 -0 0</pose>
        <axis>
          <dynamics>
            <damping>0</damping>
            <friction>0</friction>
            <spring_reference>0</spring_reference>
            <spring_stiffness>0</spring_stiffness>
          </dynamics>
          <xyz>0 0 1</xyz>
          <use_parent_model_frame>1</use_parent_model_frame>
          <limit>
            <lower>-1e+16</lower>
            <upper>1e+16</upper>
          </limit>
        </axis>
      </joint>
      <joint name='l_finger_2_link_paraproximal_bar_paramedian_hinge_couple' type='revolute'>
        <parent>l_finger_2_link_paramedian_hinge</parent>
        <child>l_finger_2_link_paraproximal_bar</child>
        <pose>0.0577 0 0 0 -0 0</pose>
        <axis>
          <dynamics>
            <damping>0</damping>
            <friction>0</friction>
            <spring_reference>0</spring_reference>
            <spring_stiffness>0</spring_stiffness>
          </dynamics>
          <xyz>0 0 1</xyz>
          <use_parent_model_frame>1</use_parent_model_frame>
          <limit>
            <lower>-1e+16</lower>
            <upper>1e+16</upper>
          </limit>
        </axis>
      </joint>
      <joint name='l_finger_middle_link_proximal_actuating_bar_median_actuating_hinge_couple' type='revolute'>
        <parent>l_finger_middle_link_median_actuating_hinge</parent>
        <child>l_finger_middle_link_proximal_actuating_bar</child>
        <pose>0.05398 0 0 0 -0 0</pose>
        <axis>
          <dynamics>
            <damping>0</damping>
            <friction>0</friction>
            <spring_reference>0</spring_reference>
            <spring_stiffness>0</spring_stiffness>
          </dynamics>
          <xyz>0 0 1</xyz>
          <use_parent_model_frame>1</use_parent_model_frame>
          <limit>
            <lower>-1e+16</lower>
            <upper>1e+16</upper>
          </limit>
        </axis>
      </joint>
      <joint name='l_finger_middle_link_median_bar_link_3_couple' type='revolute'>
        <parent>l_finger_middle_link_3</parent>
        <child>l_finger_middle_link_median_bar</child>
        <pose>0.0381 0 0 0 -0 0</pose>
        <axis>
          <dynamics>
            <damping>0</damping>
            <friction>0</friction>
            <spring_reference>0</spring_reference>
            <spring_stiffness>0</spring_stiffness>
          </dynamics>
          <xyz>0 0 1</xyz>
          <use_parent_model_frame>1</use_parent_model_frame>
          <limit>
            <lower>-1e+16</lower>
            <upper>1e+16</upper>
          </limit>
        </axis>
      </joint>
      <joint name='l_finger_middle_link_paramedian_bar_paradistal_hinge_couple' type='revolute'>
        <parent>l_finger_middle_link_paradistal_hinge</parent>
        <child>l_finger_middle_link_median_bar_underactuated</child>
        <pose>0.0381 0 0 0 -0 0</pose>
        <axis>
          <dynamics>
            <damping>0</damping>
            <friction>0</friction>
            <spring_reference>0</spring_reference>
            <spring_stiffness>0</spring_stiffness>
          </dynamics>
          <xyz>0 0 1</xyz>
          <use_parent_model_frame>1</use_parent_model_frame>
          <limit>
            <lower>-1e+16</lower>
            <upper>1e+16</upper>
          </limit>
        </axis>
      </joint>
      <joint name='l_finger_middle_link_paradistal_hinge_link_3_couple' type='revolute'>
        <parent>l_finger_middle_link_paradistal_hinge</parent>
        <child>l_finger_middle_link_3</child>
        <pose>0.0381 0 0 0 -0 0</pose>
        <axis>
          <dynamics>
            <damping>0</damping>
            <friction>0</friction>
            <spring_reference>0</spring_reference>
            <spring_stiffness>0</spring_stiffness>
          </dynamics>
          <xyz>0 0 1</xyz>
          <use_parent_model_frame>1</use_parent_model_frame>
          <limit>
            <lower>-1e+16</lower>
            <upper>1e+16</upper>
          </limit>
        </axis>
      </joint>
      <joint name='l_finger_middle_link_paraproximal_bar_paramedian_hinge_couple' type='revolute'>
        <parent>l_finger_middle_link_paramedian_hinge</parent>
        <child>l_finger_middle_link_paraproximal_bar</child>
        <pose>0.0577 0 0 0 -0 0</pose>
        <axis>
          <dynamics>
            <damping>0</damping>
            <friction>0</friction>
            <spring_reference>0</spring_reference>
            <spring_stiffness>0</spring_stiffness>
          </dynamics>
          <xyz>0 0 1</xyz>
          <use_parent_model_frame>1</use_parent_model_frame>
          <limit>
            <lower>-1e+16</lower>
            <upper>1e+16</upper>
          </limit>
        </axis>
      </joint>
      <static>0</static>

      <!-- Gripper controller -->

      <plugin name='left_robotiq_hand_plugin' filename='libRobotiqHandPlugin.so'>
        <side>left</side>
        <kp_position>10.0</kp_position>
        <kd_position>0.5</kd_position>
      </plugin>
      
      <!-- Gripper Raiser and Joints -->
      
        <link name="raiser">
            <pose>0.25 0.0 0.0 0 0 0</pose>
            <inertial>
                <pose>0 0 0 0 0 0</pose>
                <inertia>
                    <ixx>0.01</ixx>
                    <ixy>0</ixy>
                    <ixz>0</ixz>
                    <iyy>0.01</iyy>
                    <iyz>0</iyz>
                    <izz>0.01</izz>
                </inertia>
                <mass>10.0</mass>
            </inertial>
            <collision name="collision">
                <geometry>
                    <box>
                        <size>0.02 0.05 0.20</size>
                    </box>
                </geometry>
            </collision>
            <visual name="visual">
                <geometry>
                    <box>
                        <size>0.02 0.05 0.20</size>
                    </box>
                </geometry>
                <material>
                    <script>Gazebo/Purple</script>
                </material>
            </visual>
        </link>

      <!-- Joints on gripper palm and raiser and raiser and robot's chassis -->
        <joint name="gripper_raiser_palm" type="prismatic">
            <parent>raiser</parent>
            <child>base_link</child>
            <axis>
                <limit>
                    <lower>0.01</lower>
                    <upper>0.2</upper>
                </limit>
                <xyz>0 0 1</xyz>
            </axis>
        </joint>
        <joint name="arm_gripper_joint" type="revolute">
          <parent>chassis</parent>
          <child>raiser</child>
          <axis>
            <limit>
              <lower>0</lower>
              <upper>0</upper>
            </limit>
            <xyz>0 0 1</xyz>
          </axis>
        </joint>

    </model>
  </world>
</sdf>